Workbook

Sheet Entry Sheet
A2: =Settings!A3 -> DECOUPES
B3: Week 1 | D3: Week 2 | F3: Week 3 | H3: Week 4 | J3: Week 5 | L3: Week 6 | N3: Week 7 | P3: Week 8 | R3: Week 9 | T3: Week 10 | V3: Week 11 | X3: Week 12 | Z3: Week 13 | AB3: Week 14 | AD3: Finale
A4: Team Rank | B4: 5 | D4: 3 | F4: 2 | H4: 3 | J4: 4 | L4: 5 | N4: 5 | P4: 4 | R4: 5 | T4: 6 | V4: 6 | X4: 5 | Z4: 4 | AB4: 3
A5: QB | B5: J. DANIELS | C5: 24.82 | D5: J. DANIELS | E5: 25.6 | F5: D. JONES | G5: 20.42 | H5: J. FIELDS | I5: 32.44 | J5: J. FIELDS | K5: 34.22 | L5: D. PRESCOTT | M5: 31.74 | N5: D. PRESCOTT | O5: 32.16 | P5: D. PRESCOTT | Q5: 7.02 | R5: D. PRESCOTT | S5: 18.8 | T5: J. DART | U5: 28.68 | V5: D. PRESCOTT | W5: 36.12 | X5: D. PRESCOTT | Y5: 33.76 | Z5: D. PRESCOTT | AA5: 28.1 | AB5: D. PRESCOTT | AC5: 23.14
A6: RB | B6: C. BROWN | C6: 15.2 | D6: C. BROWN | E6: 10.1 | F6: C. BROWN | G6: 7 | H6: B. IRVING | I6: 28 | J6: W. MARKS | K6: 3.1 | L6: R. WHITE | M6: 19.3 | N6: J. GIBBS | O6: 39.5 | P6: R. WHITE | Q6: 9.4 | R6: J. GIBBS | S6: 6.7 | T6: J. GIBBS | U6: 40.7 | V6: J. WARREN | W6: 9.7 | X6: J. GIBBS | Y6: 58.9 | Z6: J. GIBBS | AA6: 13.6 | AB6: B. IRVING | AC6: 17.6
A7: RB | B7: B. IRVING | C7: 15.9 | D7: B. IRVING | E7: 19.8 | F7: B. IRVING | G7: 16.4 | H7: T. BENSON | I7: 11.2 | J7: R. WHITE | K7: 24.5 | L7: J. WARREN | M7: 9.4 | N7: J. WARREN | O7: 22.4 | P7: J. WARREN | Q7: 10.6 | R7: J. WARREN | S7: 18.5 | T7: T. TRACY | U7: 9.5 | V7: R. WHITE | W7: 9.2 | X7: J. WARREN | Y7: 14.6 | Z7: J. WARREN | AA7: 13.4 | AB7: J. GIBBS | AC7: 38.2
A8: RB
A9: WR | B9: C. LAMB | C9: 19 | D9: C. LAMB | E9: 21.2 | F9: C. LAMB | G9: 0 | H9: J. MEYERS | I9: 7 | J9: J. MEYERS | K9: 7.2 | L9: J. MEYERS | M9: 7.9 | N9: C. LAMB | O9: 23 | P9: C. LAMB | Q9: 14.7 | R9: C. LAMB | S9: 15.5 | T9: W. ROBINSON | U9: 12.2 | V9: C. LAMB | W9: 17.6 | X9: C. LAMB | Y9: 11.5 | Z9: C. LAMB | AA9: 25.2 | AB9: C. LAMB | AC9: 19.1
A10: WR | B10: J. MEYERS | C10: 17.7 | D10: J. MEYERS | E10: 12.8 | F10: J. MEYERS | G10: 9.3 | H10: C. GODWIN JR. | I10: 5.6 | J10: C. GODWIN JR. | K10: 5.6 | L10: R. SHAHEED | M10: 7.85 | N10: R. RICE | O10: 23.2 | P10: R. RICE | Q10: 25.7 | R10: R. RICE | S10: 18.8 | T10: G. WILSON | U10: 0 | V10: R. RICE | W10: 9.8 | X10: R. RICE | Y10: 25.1 | Z10: R. RICE | AA10: 29.5 | AB10: R. RICE | AC10: 7.4
A11: WR | B11: T. MCLAURIN | C11: 4.7 | D11: T. MCLAURIN | E11: 9.8 | F11: W. ROBINSON | G11: 3.6 | H11: D. MOONEY | I11: 2.5 | J11: J. TOLBERT | K11: 0 | L11: L. MCCAFFREY | M11: 16.65 | N11: L. MCCAFFREY | O11: 10.45 | P11: D. MOONEY | Q11: 2.1 | R11: K. BOUTTE | S11: 0 | T11: R. DOUBS | U11: 2.6 | V11: W. ROBINSON | W11: 7.6 | X11: W. ROBINSON | Y11: 31.7 | Z11: W. ROBINSON | AA11: 10.4 | AB11: J. MEYERS | AC11: 15.1
A12: WR
A13: TE | B13: T. KELCE | C13: 12.7 | D13: T. KELCE | E13: 10.1 | F13: T. KELCE | G13: 6.6 | H13: T. KRAFT | I13: 10.6 | J13: T. KELCE | K13: 19.1 | L13: T. KELCE | M13: 13.8 | N13: T. KRAFT | O13: 16.8 | P13: T. KRAFT | Q13: 34.3 | R13: T. KRAFT | S13: 4 | T13: D. KINCAID | U13: 5.7 | V13: T. KELCE | W13: 24.1 | X13: T. KELCE | Y13: 8.5 | Z13: T. KELCE | AA13: 15.5 | AB13: T. KELCE | AC13: 1.8
A14: FLEX | B14: S. DIGGS | C14: 11.7 | D14: S. DIGGS | E14: 7.2 | F14: T. KRAFT | G14: 5.9 | H14: C. BROWN | I14: 11.1 | J14: C. BROWN | K14: 12.6 | L14: J. GIBBS | M14: 9.2 | N14: R. WHITE | O14: 9.4 | P14: A. KAMARA | Q14: 7.1 | R14: T. TRACY | S14: 7.2 | T14: J. WARREN | U14: 12.5 | V14: J. GIBBS | W14: 21.8 | X14: J. MEYERS | Y14: 15 | Z14: J. MEYERS | AA14: 21.4 | AB14: J. WARREN | AC14: 16.95
A15: D/ST | B15: LAR D/ST | C15: 21.68 | D15: BUF D/ST | E15: 25.11 | F15: BUF D/ST | G15: 10.95 | H15: BUF D/ST | I15: 18.23 | J15: LAR D/ST | K15: 4.78 | L15: LAR D/ST | M15: 24.25 | N15: KC D/ST | O15: 15.2 | P15: KC D/ST | Q15: 20.34 | R15: LAR D/ST | S15: 13.88 | T15: CLE D/ST | U15: 18.5 | V15: MIA D/ST | W15: 8.29 | X15: JAX D/ST | Y15: 19.39 | Z15: JAX D/ST | AA15: 25.02 | AB15: LAR D/ST | AC15: 17.88
A16: K | B16: J. ELLIOTT | C16: 9 | D16: J. ELLIOTT | E16: 14 | F16: J. ELLIOTT | G16: 3 | H16: J. ELLIOTT | I16: 7 | J16: S. SHRADER | K16: 2 | L16: M. PRATER | M16: 2 | N16: K. FAIRBURN | O16: 8 | P16: K. FAIRBAIRN | Q16: 14 | R16: K. FAIRBAIRN | S16: 17 | T16: W. REICHARD | U16: 9 | V16: Z. GONZALEZ | W16: 13 | X16: Z. GONZALEZ | Y16: 17 | Z16: Z. GONZALEZ | AA16: 8 | AB16: Z. GONZALEZ | AC16: 9
A17: HC | B17: PHI HC | C17: 9.2 | D17: LAC HC | E17: 10 | F17: PHI HC | G17: 12.9 | H17: LAC HC | I17: 3.4 | J17: PHI HC | K17: 3.1 | L17: PHI HC | M17: -0.9 | N17: NE HC | O17: 15.3 | P17: NE HC | Q17: 15.6 | R17: LAC HC | S17: 11.1 | T17: SEA HC | U17: 21.2 | V17: NE HC | W17: 12.1 | X17: SEA HC | Y17: 12 | Z17: SEA HC | AA17: 19.8 | AB17: SEA HC | AC17: 23.1
A18: Total Score | B18: =SUM(C5:C17) -> 161.6 | D18: =SUM(E5:E17) -> 165.71 | F18: =SUM(G5:G17) -> 96.07 | H18: =SUM(I5:I17) -> 137.07 | J18: =SUM(K5:K17) -> 116.2 | L18: =SUM(M5:M17) -> 141.19 | N18: =SUM(O5:O17) -> 215.41 | P18: =SUM(Q5:Q17) -> 160.86 | R18: =SUM(S5:S17) -> 131.48 | T18: =SUM(U5:U17) -> 160.58 | V18: =SUM(W5:W17) -> 169.31 | X18: =SUM(Y5:Y17) -> 247.45 | Z18: =SUM(AA5:AA17) -> 209.92 | AB18: =SUM(AC5:AC17) -> 189.27 | AD18: =SUM(AE5:AE17) -> 0
A19: MVP | B19: {=IFERROR(INDEX(B5:B17,MATCH(LARGE(C5:C17,1),C5:C17,0)),"N/A")} -> J. DANIELS | C19: =IFERROR(LARGE(C5:C17,1),0) -> 24.82 | D19: {=IFERROR(INDEX(D5:D17,MATCH(LARGE(E5:E17,1),E5:E17,0)),"N/A")} -> J. DANIELS | E19: =IFERROR(LARGE(E5:E17,1),0) -> 25.6 | F19: {=IFERROR(INDEX(F5:F17,MATCH(LARGE(G5:G17,1),G5:G17,0)),"N/A")} -> D. JONES | G19: =IFERROR(LARGE(G5:G17,1),0) -> 20.42 | H19: {=IFERROR(INDEX(H5:H17,MATCH(LARGE(I5:I17,1),I5:I17,0)),"N/A")} -> J. FIELDS | I19: =IFERROR(LARGE(I5:I17,1),0) -> 32.44 | J19: {=IFERROR(INDEX(J5:J17,MATCH(LARGE(K5:K17,1),K5:K17,0)),"N/A")} -> J. FIELDS | K19: =IFERROR(LARGE(K5:K17,1),0) -> 34.22 | L19: {=IFERROR(INDEX(L5:L17,MATCH(LARGE(M5:M17,1),M5:M17,0)),"N/A")} -> D. PRESCOTT | M19: =IFERROR(LARGE(M5:M17,1),0) -> 31.74 | N19: {=IFERROR(INDEX(N5:N17,MATCH(LARGE(O5:O17,1),O5:O17,0)),"N/A")} -> J. GIBBS | O19: =IFERROR(LARGE(O5:O17,1),0) -> 39.5 | P19: {=IFERROR(INDEX(P5:P17,MATCH(LARGE(Q5:Q17,1),Q5:Q17,0)),"N/A")} -> T. KRAFT | Q19: =IFERROR(LARGE(Q5:Q17,1),0) -> 34.3 | R19: {=IFERROR(INDEX(R5:R17,MATCH(LARGE(S5:S17,1),S5:S17,0)),"N/A")} -> D. PRESCOTT | S19: =IFERROR(LARGE(S5:S17,1),0) -> 18.8 | T19: {=IFERROR(INDEX(T5:T17,MATCH(LARGE(U5:U17,1),U5:U17,0)),"N/A")} -> J. GIBBS | U19: =IFERROR(LARGE(U5:U17,1),0) -> 40.7 | V19: {=IFERROR(INDEX(V5:V17,MATCH(LARGE(W5:W17,1),W5:W17,0)),"N/A")} -> D. PRESCOTT | W19: =IFERROR(LARGE(W5:W17,1),0) -> 36.12 | X19: {=IFERROR(INDEX(X5:X17,MATCH(LARGE(Y5:Y17,1),Y5:Y17,0)),"N/A")} -> J. GIBBS | Y19: =IFERROR(LARGE(Y5:Y17,1),0) -> 58.9 | Z19: {=IFERROR(INDEX(Z5:Z17,MATCH(LARGE(AA5:AA17,1),AA5:AA17,0)),"N/A")} -> R. RICE | AA19: =IFERROR(LARGE(AA5:AA17,1),0) -> 29.5 | AB19: {=IFERROR(INDEX(AB5:AB17,MATCH(LARGE(AC5:AC17,1),AC5:AC17,0)),"N/A")} -> J. GIBBS | AC19: =IFERROR(LARGE(AC5:AC17,1),0) -> 38.2 | AD19: {=INDEX(AD5:AD17,MATCH(LARGE(AE5:AE17,1),AE5:AE17,0))} -> #NUM! | AE19: =LARGE(AE5:AE17,1) -> #NUM!
A20: #2 | B20: {=IFERROR(INDEX(B5:B17,MATCH(LARGE(C5:C17,2),C5:C17,0)),"N/A")} -> LAR D/ST | C20: =IFERROR(LARGE(C5:C17,2),0) -> 21.68 | D20: {=IFERROR(INDEX(D5:D17,MATCH(LARGE(E5:E17,2),E5:E17,0)),"N/A")} -> BUF D/ST | E20: =IFERROR(LARGE(E5:E17,2),0) -> 25.11 | F20: {=IFERROR(INDEX(F5:F17,MATCH(LARGE(G5:G17,2),G5:G17,0)),"N/A")} -> B. IRVING | G20: =IFERROR(LARGE(G5:G17,2),0) -> 16.4 | H20: {=IFERROR(INDEX(H5:H17,MATCH(LARGE(I5:I17,2),I5:I17,0)),"N/A")} -> B. IRVING | I20: =IFERROR(LARGE(I5:I17,2),0) -> 28 | J20: {=IFERROR(INDEX(J5:J17,MATCH(LARGE(K5:K17,2),K5:K17,0)),"N/A")} -> R. WHITE | K20: =IFERROR(LARGE(K5:K17,2),0) -> 24.5 | L20: {=IFERROR(INDEX(L5:L17,MATCH(LARGE(M5:M17,2),M5:M17,0)),"N/A")} -> LAR D/ST | M20: =IFERROR(LARGE(M5:M17,2),0) -> 24.25 | N20: {=IFERROR(INDEX(N5:N17,MATCH(LARGE(O5:O17,2),O5:O17,0)),"N/A")} -> D. PRESCOTT | O20: =IFERROR(LARGE(O5:O17,2),0) -> 32.16 | P20: {=IFERROR(INDEX(P5:P17,MATCH(LARGE(Q5:Q17,2),Q5:Q17,0)),"N/A")} -> R. RICE | Q20: =IFERROR(LARGE(Q5:Q17,2),0) -> 25.7 | R20: {=IFERROR(INDEX(R5:R17,MATCH(LARGE(S5:S17,2),S5:S17,0)),"N/A")} -> D. PRESCOTT | S20: =IFERROR(LARGE(S5:S17,2),0) -> 18.8 | T20: {=IFERROR(INDEX(T5:T17,MATCH(LARGE(U5:U17,2),U5:U17,0)),"N/A")} -> J. DART | U20: =IFERROR(LARGE(U5:U17,2),0) -> 28.68 | V20: {=IFERROR(INDEX(V5:V17,MATCH(LARGE(W5:W17,2),W5:W17,0)),"N/A")} -> T. KELCE | W20: =IFERROR(LARGE(W5:W17,2),0) -> 24.1 | X20: {=IFERROR(INDEX(X5:X17,MATCH(LARGE(Y5:Y17,2),Y5:Y17,0)),"N/A")} -> D. PRESCOTT | Y20: =IFERROR(LARGE(Y5:Y17,2),0) -> 33.76 | Z20: {=IFERROR(INDEX(Z5:Z17,MATCH(LARGE(AA5:AA17,2),AA5:AA17,0)),"N/A")} -> D. PRESCOTT | AA20: =IFERROR(LARGE(AA5:AA17,2),0) -> 28.1 | AB20: {=IFERROR(INDEX(AB5:AB17,MATCH(LARGE(AC5:AC17,2),AC5:AC17,0)),"N/A")} -> D. PRESCOTT | AC20: =IFERROR(LARGE(AC5:AC17,2),0) -> 23.14
A21: #3 | B21: {=IFERROR(INDEX(B5:B17,MATCH(LARGE(C5:C17,3),C5:C17,0)),"N/A")} -> C. LAMB | C21: =IFERROR(LARGE(C5:C17,3),0) -> 19 | D21: {=IFERROR(INDEX(D5:D17,MATCH(LARGE(E5:E17,3),E5:E17,0)),"N/A")} -> C. LAMB | E21: =IFERROR(LARGE(E5:E17,3),0) -> 21.2 | F21: {=IFERROR(INDEX(F5:F17,MATCH(LARGE(G5:G17,3),G5:G17,0)),"N/A")} -> PHI HC | G21: =IFERROR(LARGE(G5:G17,3),0) -> 12.9 | H21: {=IFERROR(INDEX(H5:H17,MATCH(LARGE(I5:I17,3),I5:I17,0)),"N/A")} -> BUF D/ST | I21: =IFERROR(LARGE(I5:I17,3),0) -> 18.23 | J21: {=IFERROR(INDEX(J5:J17,MATCH(LARGE(K5:K17,3),K5:K17,0)),"N/A")} -> T. KELCE | K21: =IFERROR(LARGE(K5:K17,3),0) -> 19.1 | L21: {=IFERROR(INDEX(L5:L17,MATCH(LARGE(M5:M17,3),M5:M17,0)),"N/A")} -> R. WHITE | M21: =IFERROR(LARGE(M5:M17,3),0) -> 19.3 | N21: {=IFERROR(INDEX(N5:N17,MATCH(LARGE(O5:O17,3),O5:O17,0)),"N/A")} -> R. RICE | O21: =IFERROR(LARGE(O5:O17,3),0) -> 23.2 | P21: {=IFERROR(INDEX(P5:P17,MATCH(LARGE(Q5:Q17,3),Q5:Q17,0)),"N/A")} -> KC D/ST | Q21: =IFERROR(LARGE(Q5:Q17,3),0) -> 20.34 | R21: {=IFERROR(INDEX(R5:R17,MATCH(LARGE(S5:S17,3),S5:S17,0)),"N/A")} -> J. WARREN | S21: =IFERROR(LARGE(S5:S17,3),0) -> 18.5 | T21: {=IFERROR(INDEX(T5:T17,MATCH(LARGE(U5:U17,3),U5:U17,0)),"N/A")} -> SEA HC | U21: =IFERROR(LARGE(U5:U17,3),0) -> 21.2 | V21: {=IFERROR(INDEX(V5:V17,MATCH(LARGE(W5:W17,3),W5:W17,0)),"N/A")} -> J. GIBBS | W21: =IFERROR(LARGE(W5:W17,3),0) -> 21.8 | X21: {=IFERROR(INDEX(X5:X17,MATCH(LARGE(Y5:Y17,3),Y5:Y17,0)),"N/A")} -> W. ROBINSON | Y21: =IFERROR(LARGE(Y5:Y17,3),0) -> 31.7 | Z21: {=IFERROR(INDEX(Z5:Z17,MATCH(LARGE(AA5:AA17,3),AA5:AA17,0)),"N/A")} -> C. LAMB | AA21: =IFERROR(LARGE(AA5:AA17,3),0) -> 25.2 | AB21: {=IFERROR(INDEX(AB5:AB17,MATCH(LARGE(AC5:AC17,3),AC5:AC17,0)),"N/A")} -> SEA HC | AC21: =IFERROR(LARGE(AC5:AC17,3),0) -> 23.1
A23: =Settings!A4 -> POPEYES
B24: Week 1 | D24: Week 2 | F24: Week 3 | H24: Week 4 | J24: Week 5 | L24: Week 6 | N24: Week 7 | P24: Week 8 | R24: Week 9 | T24: Week 10 | V24: Week 11 | X24: Week 12 | Z24: Week 13 | AB24: Week 14 | AD24: Finale
A25: Team Rank | B25: 1 | D25: 4 | F25: 4 | H25: 1 | J25: 1 | L25: 1 | N25: 2 | P25: 3 | R25: 4 | T25: 4 | V25: 4 | X25: 3 | Z25: 5 | AB25: 5
A26: QB | B26: B. MAYFIELD | C26: 29.48 | D26: B. MAYFIELD | E26: 26.6 | F26: B. MAYFIELD | G26: 21.92 | H26: M. STAFFORD | I26: 38.2 | J26: M. STAFFORD | K26: 35.26 | L26: M. STAFFORD | M26: 13.34 | N26: B. MAYFIELD | O26: 13.52 | P26: B. MAYFIELD | Q26: 5.28 | R26: S. DARNOLD | S26: 39 | T26: B. MAYFIELD | U26: 31.52 | V26: B. MAYFIELD | W26: 19.32 | X26: S. DARNOLD | Y26: 22.96 | Z26: S. DARNOLD | AA26: 3.52 | AB26: B. MAYFIELD | AC26: 12.48
A27: RB | B27: D. ACHANE | C27: 17.2 | D27: D. ACHANE | E27: 27.3 | F27: D. ACHANE | G27: 17.3 | H27: D. ACHANE | I27: 19.1 | J27: D. ACHANE | K27: 17.6 | L27: D. ACHANE | M27: 33.6 | N27: D. ACHANE | O27: 14.1 | P27: D. ACHANE | Q27: 21.9 | R27: D. ACHANE | S27: 18 | T27: D. ACHANE | U27: 43.7 | V27: D. ACHANE | W27: 24.6 | X27: K. WALKER | Y27: 14.2 | Z27: D. ACHANE | AA27: 22.6 | AB27: D. ACHANE | AC27: 18.2
A28: RB | B28: T. HENDERSON | C28: 13.75 | D28: T. HENDERSON | E28: 6.3 | F28: K. WALKER III | G28: 19.6 | H28: J. MASON | I28: 11.8 | J28: J. MASON | K28: 13.9 | L28: T. HENDERSON | M28: 5.5 | N28: J. MASON | O28: 13.2 | P28: J. MASON | Q28: 2 | R28: B. KNIGHT | S28: 7.6 | T28: T. HENDERSON | U28: 30.4 | V28: T. HENDERSON | W28: 34.2 | X28: T. HENDERSON | Y28: 12.9 | Z28: T. HENDERSON | AA28: 12.7 | AB28: K. WALKER | AC28: 4.8
A29: RB
A30: WR | B30: J. JEFFERSON | C30: 14.9 | D30: J. JEFFERSON | E30: 11.1 | F30: J. JEFFERSON | G30: 12.5 | H30: J. JEFFERSON | I30: 23.6 | J30: J. JEFFERSON | K30: 20.3 | L30: P. NACUA | M30: 4.8 | N30: J. JEFFERSON | O30: 12.9 | P30: J. JEFFERSON | Q30: 14.4 | R30: J. JEFFERSON | S30: 16.7 | T30: J. JEFFERSON | U30: 7.7 | V30: J. JEFFERSON | W30: 11.1 | X30: J. JEFFERSON | Y30: 8.8 | Z30: J. JEFFERSON | AA30: 2.4 | AB30: J. JEFFERSON | AC30: 3.1
A31: WR | B31: P. NACUA | C31: 24.2 | D31: P. NACUA | E31: 27.7 | F31: P. NACUA | G31: 23.9 | H31: P. NACUA | I31: 37 | J31: P. NACUA | K31: 24.5 | L31: E. EGBUKA | M31: 4.4 | N31: B. THOMAS JR. | O31: 6.1 | P31: E. EGBUKA | Q31: 6.5 | R31: P. NACUA | S31: 22.9 | T31: P. NACUA | U31: 17.4 | V31: P. NACUA | W31: 14.5 | X31: P. NACUA | Y31: 16.7 | Z31: P. NACUA | AA31: 13.2 | AB31: P. NACUA | AC31: 36.7
A32: WR | B32: B. THOMAS JR | C32: 9.1 | D32: B. THOMAS JR | E32: 8.9 | F32: B. THOMAS JR | G32: 7.5 | H32: E. EGBUKA | I32: 21.2 | J32: E. EGBUKA | K32: 32.3 | L32: D. SMITH | M32: 8.9 | N32: D. SMITH | O32: 34.3 | P32: D. SMITH | Q32: 14.4 | R32: B. THOMAS | S32: 8.5 | T32: E. EGBUKA | U32: 24.5 | V32: E. EGBUKA | W32: 9 | X32: E. EGBUKA | Y32: 6.2 | Z32: E. EGBUKA | AA32: 8.2 | AB32: E. EGBUKA | AC32: 3.5
A33: WR
A34: TE | B34: T. HOCKENSON | C34: 4.5 | D34: T. HOCKENSON | E34: 2.2 | F34: K. PITTS SR | G34: 7.9 | H34: T. HOCKENSON | I34: 7.9 | J34: T. HOCKENSON | K34: 9.8 | L34: D. WALLER | M34: 9.2 | N34: K. PITTS SR. | O34: 13.2 | P34: K. PITTS SR. | Q34: 14.9 | R34: K. PITTS | S34: 7.8 | T34: K. PITTS | U34: 5.8 | V34: D. SCHULTZ | W34: 11.1 | X34: K. PITTS | Y34: 4.5 | Z34: K. PITTS | AA34: 15.2 | AB34: H. FANNIN | AC34: 26.4
A35: FLEX | B35: K. WALKER III | C35: 6.4 | D35: E. EGBUKA | E35: 12.9 | F35: J. MASON | G35: 26.2 | H35: K. WALKER III | I35: 13.9 | J35: K. WALKER III | K35: 10.6 | L35: K. WALKER III | M35: 5.7 | N35: K. WALKER III | O35: 8.3 | P35: T.J. HOCKENSON | Q35: 4.6 | R35: K. WALKER | S35: 9.2 | T35: D. SMITH | U35: 16.9 | V35: D. SMITH | W35: 1.8 | X35: D. SMITH | Y35: 14.9 | Z35: D. SMITH | AA35: 9.8 | AB35: D. NEAL | AC35: 17.3
A36: D/ST | B36: NE D/ST | C36: 15.83 | D36: IND D/ST | E36: 7.32 | F36: IND D/ST | G36: 27.2 | H36: NE D/ST | I36: 28.76 | J36: IND D/ST | K36: 26.7 | L36: IND D/ST | M36: 8.75 | N36: NE D/ST | O36: 27 | P36: IND D/ST | Q36: 16.74 | R36: JAX D/ST | S36: 12.07 | T36: BUF D/ST | U36: 6.21 | V36: DAL D/ST | W36: 23.67 | X36: CLE D/ST | Y36: 39.18 | Z36: IND D/ST | AA36: 11.37 | AB36: CLE D/ST | AC36: 10.93
A37: K | B37: T. LOOP | C37: 14 | D37: T. LOOP | E37: 12 | F37: T. LOOP | G37: 7 | H37: T. LOOP | I37: 9 | J37: T. LOOP | K37: 3 | L37: J. ELLIOTT | M37: 6 | N37: J. ELLIOTT | O37: 2.5 | P37: T. LOOP | Q37: 13 | R37: T. LOOP | S37: 4 | T37: T. LOOP | U37: 13 | V37: T. LOOP | W37: 12 | X37: T. LOOP | Y37: 11 | Z37: T. LOOP | AA37: 2 | AB37: T. LOOP | AC37: 10
A38: HC | B38: LAR HC | C38: 7.2 | D38: LAR HC | E38: 13.9 | F38: SEA HC | G38: 25.2 | H38: SEA HC | I38: 8.9 | J38: SEA HC | K38: 8.5 | L38: LAC HC | M38: 10.7 | N38: CHI HC | O38: 11.8 | P38: CHI HC | Q38: 0.8 | R38: CHI HC | S38: 17.1 | T38: PHI HC | U38: 5 | V38: PHI HC | W38: 7.8 | X38: PHI HC | Y38: 4.3 | Z38: PHI HC | AA38: 1.5 | AB38: DEN HC | AC38: 10.2
A39: Total Score | B39: =SUM(C26:C38) -> 156.56 | D39: =SUM(E26:E38) -> 156.22 | F39: =SUM(G26:G38) -> 196.22 | H39: =SUM(I26:I38) -> 219.36 | J39: =SUM(K26:K38) -> 202.46 | L39: =SUM(M26:M38) -> 110.89 | N39: =SUM(O26:O38) -> 156.92 | P39: =SUM(Q26:Q38) -> 114.52 | R39: =SUM(S26:S38) -> 162.87 | T39: =SUM(U26:U38) -> 202.13 | V39: =SUM(W26:W38) -> 169.09 | X39: =SUM(Y26:Y38) -> 155.64 | Z39: =SUM(AA26:AA38) -> 102.49 | AB39: =SUM(AC26:AC38) -> 153.61 | AD39: =SUM(AE26:AE38) -> 0
A40: MVP | B40: {=IFERROR(INDEX(B26:B38,MATCH(LARGE(C26:C38,1),C26:C38,0)),"N/A")} -> B. MAYFIELD | C40: =IFERROR(LARGE(C26:C38,1),0) -> 29.48 | D40: {=IFERROR(INDEX(D26:D38,MATCH(LARGE(E26:E38,1),E26:E38,0)),"N/A")} -> P. NACUA | E40: =IFERROR(LARGE(E26:E38,1),0) -> 27.7 | F40: {=IFERROR(INDEX(F26:F38,MATCH(LARGE(G26:G38,1),G26:G38,0)),"N/A")} -> IND D/ST | G40: =IFERROR(LARGE(G26:G38,1),0) -> 27.2 | H40: {=IFERROR(INDEX(H26:H38,MATCH(LARGE(I26:I38,1),I26:I38,0)),"N/A")} -> M. STAFFORD | I40: =IFERROR(LARGE(I26:I38,1),0) -> 38.2 | J40: {=IFERROR(INDEX(J26:J38,MATCH(LARGE(K26:K38,1),K26:K38,0)),"N/A")} -> M. STAFFORD | K40: =IFERROR(LARGE(K26:K38,1),0) -> 35.26 | L40: {=IFERROR(INDEX(L26:L38,MATCH(LARGE(M26:M38,1),M26:M38,0)),"N/A")} -> D. ACHANE | M40: =IFERROR(LARGE(M26:M38,1),0) -> 33.6 | N40: {=IFERROR(INDEX(N26:N38,MATCH(LARGE(O26:O38,1),O26:O38,0)),"N/A")} -> D. SMITH | O40: =IFERROR(LARGE(O26:O38,1),0) -> 34.3 | P40: {=IFERROR(INDEX(P26:P38,MATCH(LARGE(Q26:Q38,1),Q26:Q38,0)),"N/A")} -> D. ACHANE | Q40: =IFERROR(LARGE(Q26:Q38,1),0) -> 21.9 | R40: {=IFERROR(INDEX(R26:R38,MATCH(LARGE(S26:S38,1),S26:S38,0)),"N/A")} -> S. DARNOLD | S40: =IFERROR(LARGE(S26:S38,1),0) -> 39 | T40: {=IFERROR(INDEX(T26:T38,MATCH(LARGE(U26:U38,1),U26:U38,0)),"N/A")} -> D. ACHANE | U40: =IFERROR(LARGE(U26:U38,1),0) -> 43.7 | V40: {=IFERROR(INDEX(V26:V38,MATCH(LARGE(W26:W38,1),W26:W38,0)),"N/A")} -> T. HENDERSON | W40: =IFERROR(LARGE(W26:W38,1),0) -> 34.2 | X40: {=IFERROR(INDEX(X26:X38,MATCH(LARGE(Y26:Y38,1),Y26:Y38,0)),"N/A")} -> CLE D/ST | Y40: =IFERROR(LARGE(Y26:Y38,1),0) -> 39.18 | Z40: {=IFERROR(INDEX(Z26:Z38,MATCH(LARGE(AA26:AA38,1),AA26:AA38,0)),"N/A")} -> D. ACHANE | AA40: =IFERROR(LARGE(AA26:AA38,1),0) -> 22.6 | AB40: {=IFERROR(INDEX(AB26:AB38,MATCH(LARGE(AC26:AC38,1),AC26:AC38,0)),"N/A")} -> P. NACUA | AC40: =IFERROR(LARGE(AC26:AC38,1),0) -> 36.7 | AD40: {=INDEX(AD26:AD38,MATCH(LARGE(AE26:AE38,1),AE26:AE38,0))} -> #NUM! | AE40: =LARGE(AE26:AE38,1) -> #NUM!
A41: #2 | B41: {=IFERROR(INDEX(B26:B38,MATCH(LARGE(C26:C38,2),C26:C38,0)),"N/A")} -> P. NACUA | C41: =IFERROR(LARGE(C26:C38,2),0) -> 24.2 | D41: {=IFERROR(INDEX(D26:D38,MATCH(LARGE(E26:E38,2),E26:E38,0)),"N/A")} -> D. ACHANE | E41: =IFERROR(LARGE(E26:E38,2),0) -> 27.3 | F41: {=IFERROR(INDEX(F26:F38,MATCH(LARGE(G26:G38,2),G26:G38,0)),"N/A")} -> J. MASON | G41: =IFERROR(LARGE(G26:G38,2),0) -> 26.2 | H41: {=IFERROR(INDEX(H26:H38,MATCH(LARGE(I26:I38,2),I26:I38,0)),"N/A")} -> P. NACUA | I41: =IFERROR(LARGE(I26:I38,2),0) -> 37 | J41: {=IFERROR(INDEX(J26:J38,MATCH(LARGE(K26:K38,2),K26:K38,0)),"N/A")} -> E. EGBUKA | K41: =IFERROR(LARGE(K26:K38,2),0) -> 32.3 | L41: {=IFERROR(INDEX(L26:L38,MATCH(LARGE(M26:M38,2),M26:M38,0)),"N/A")} -> M. STAFFORD | M41: =IFERROR(LARGE(M26:M38,2),0) -> 13.34 | N41: {=IFERROR(INDEX(N26:N38,MATCH(LARGE(O26:O38,2),O26:O38,0)),"N/A")} -> NE D/ST | O41: =IFERROR(LARGE(O26:O38,2),0) -> 27 | P41: {=IFERROR(INDEX(P26:P38,MATCH(LARGE(Q26:Q38,2),Q26:Q38,0)),"N/A")} -> IND D/ST | Q41: =IFERROR(LARGE(Q26:Q38,2),0) -> 16.74 | R41: {=IFERROR(INDEX(R26:R38,MATCH(LARGE(S26:S38,2),S26:S38,0)),"N/A")} -> P. NACUA | S41: =IFERROR(LARGE(S26:S38,2),0) -> 22.9 | T41: {=IFERROR(INDEX(T26:T38,MATCH(LARGE(U26:U38,2),U26:U38,0)),"N/A")} -> B. MAYFIELD | U41: =IFERROR(LARGE(U26:U38,2),0) -> 31.52 | V41: {=IFERROR(INDEX(V26:V38,MATCH(LARGE(W26:W38,2),W26:W38,0)),"N/A")} -> D. ACHANE | W41: =IFERROR(LARGE(W26:W38,2),0) -> 24.6 | X41: {=IFERROR(INDEX(X26:X38,MATCH(LARGE(Y26:Y38,2),Y26:Y38,0)),"N/A")} -> S. DARNOLD | Y41: =IFERROR(LARGE(Y26:Y38,2),0) -> 22.96 | Z41: {=IFERROR(INDEX(Z26:Z38,MATCH(LARGE(AA26:AA38,2),AA26:AA38,0)),"N/A")} -> K. PITTS | AA41: =IFERROR(LARGE(AA26:AA38,2),0) -> 15.2 | AB41: {=IFERROR(INDEX(AB26:AB38,MATCH(LARGE(AC26:AC38,2),AC26:AC38,0)),"N/A")} -> H. FANNIN | AC41: =IFERROR(LARGE(AC26:AC38,2),0) -> 26.4
A42: #3 | B42: {=IFERROR(INDEX(B26:B38,MATCH(LARGE(C26:C38,3),C26:C38,0)),"N/A")} -> D. ACHANE | C42: =IFERROR(LARGE(C26:C38,3),0) -> 17.2 | D42: {=IFERROR(INDEX(D26:D38,MATCH(LARGE(E26:E38,3),E26:E38,0)),"N/A")} -> B. MAYFIELD | E42: =IFERROR(LARGE(E26:E38,3),0) -> 26.6 | F42: {=IFERROR(INDEX(F26:F38,MATCH(LARGE(G26:G38,3),G26:G38,0)),"N/A")} -> SEA HC | G42: =IFERROR(LARGE(G26:G38,3),0) -> 25.2 | H42: {=IFERROR(INDEX(H26:H38,MATCH(LARGE(I26:I38,3),I26:I38,0)),"N/A")} -> NE D/ST | I42: =IFERROR(LARGE(I26:I38,3),0) -> 28.76 | J42: {=IFERROR(INDEX(J26:J38,MATCH(LARGE(K26:K38,3),K26:K38,0)),"N/A")} -> IND D/ST | K42: =IFERROR(LARGE(K26:K38,3),0) -> 26.7 | L42: {=IFERROR(INDEX(L26:L38,MATCH(LARGE(M26:M38,3),M26:M38,0)),"N/A")} -> LAC HC | M42: =IFERROR(LARGE(M26:M38,3),0) -> 10.7 | N42: {=IFERROR(INDEX(N26:N38,MATCH(LARGE(O26:O38,3),O26:O38,0)),"N/A")} -> D. ACHANE | O42: =IFERROR(LARGE(O26:O38,3),0) -> 14.1 | P42: {=IFERROR(INDEX(P26:P38,MATCH(LARGE(Q26:Q38,3),Q26:Q38,0)),"N/A")} -> K. PITTS SR. | Q42: =IFERROR(LARGE(Q26:Q38,3),0) -> 14.9 | R42: {=IFERROR(INDEX(R26:R38,MATCH(LARGE(S26:S38,3),S26:S38,0)),"N/A")} -> D. ACHANE | S42: =IFERROR(LARGE(S26:S38,3),0) -> 18 | T42: {=IFERROR(INDEX(T26:T38,MATCH(LARGE(U26:U38,3),U26:U38,0)),"N/A")} -> T. HENDERSON | U42: =IFERROR(LARGE(U26:U38,3),0) -> 30.4 | V42: {=IFERROR(INDEX(V26:V38,MATCH(LARGE(W26:W38,3),W26:W38,0)),"N/A")} -> DAL D/ST | W42: =IFERROR(LARGE(W26:W38,3),0) -> 23.67 | X42: {=IFERROR(INDEX(X26:X38,MATCH(LARGE(Y26:Y38,3),Y26:Y38,0)),"N/A")} -> P. NACUA | Y42: =IFERROR(LARGE(Y26:Y38,3),0) -> 16.7 | Z42: {=IFERROR(INDEX(Z26:Z38,MATCH(LARGE(AA26:AA38,3),AA26:AA38,0)),"N/A")} -> P. NACUA | AA42: =IFERROR(LARGE(AA26:AA38,3),0) -> 13.2 | AB42: {=IFERROR(INDEX(AB26:AB38,MATCH(LARGE(AC26:AC38,3),AC26:AC38,0)),"N/A")} -> D. ACHANE | AC42: =IFERROR(LARGE(AC26:AC38,3),0) -> 18.2
...

Sheet Weekly Scores
A1: walk | B1: WEEK | C1: GAME | D1: TEAM 1 RANK | E1: DIVISON | F1: Away Team | G1: TEAM 1 SCORE | H1: Home Team | I1: TEAM 2 | J1: DIVISON | K1: TEAM 2 RANK | L1: MOTW RANKING | M1: GAME # | N1: WINNER | O1: OPPOSING TEAM | P1: BLOWOUT | Q1: SCORE GAP | R1: COMBINED SCORE | S1: MOTW | T1: TEAM WITH HIGHEST SCORE | U1: UPSET | V1: Week | AH1: LOW SCORE GAP RANK | AI1: HIGH SCORE GAP RANK | AJ1: LOW COMBINED SCORE RANK | AK1: HIGH COMBINED SCORE RANK | AL1: GAME QUALITY | AM1: BEST GAME QUALITY RANK | AN1: WORST GAME QUALITY RANK | AP1: MOTW BEST GAME QUALITY RANK | AQ1: MOTW RANKING | AR1: UPSET MOTW RANK | AS1: UPSET RANK | AV1: ="Top 5 Greatest "& Settings!$R$3& " MOTW Regular Season Games - PVE FFL" -> Top 5 Greatest 2025 MOTW Regular Season Games - PVE FFL | BG1: Rank | BH1: Team Name | BI1: Overall Wins | BJ1: Overall Losses | BK1: Overall Win % | BL1: Division Name | BM1: Divisional Wins | BN1: Divisonal Losses | BO1: Divisional Win % | BP1: MOTW Wins | BQ1: MOTW Losses | BR1: MOTW Win % | BS1: MOTW GAMES PLAY | BT1: MOTW RANK | BU1: UPSETS | BW1: BLOWOUTS | BX1: AWAY Wins | BY1: AWAY Losses | BZ1: Away Win % | CA1: HOME Wins | CB1: HOME Losses | CC1: HOME Win % | CE1: Schedule Competivness | CF1: SOS L | CG1: SOS R
A2: 1 | B2: {=INDEX(Settings!H$2:H$72, ROW())} -> WEEK 1 | C2: {=INDEX(Settings!I$2:I$72, ROW())} -> GAME 1 | D2: {=INDEX('BACKEND 1'!$V$28:$AK$38, MATCH(F2, 'BACKEND 1'!$V$28:$V$38, 0), MATCH(B2, 'BACKEND 1'!$V$28:$AK$28, 0))} -> 10 | E2: =VLOOKUP(F2, Settings!$A$3:$C$12, 3, FALSE) -> PRODIGY | F2: {=INDEX(Settings!J$2:J$72, ROW())} -> KINGS | G2: =SUMIFS('All-Stars'!E:E, 'All-Stars'!B:B, F2, 'All-Stars'!F:F, B2) -> 142.22 | H2: =SUMIFS('All-Stars'!E:E, 'All-Stars'!B:B, I2, 'All-Stars'!F:F, B2) -> 156.47 | I2: {=INDEX(Settings!K$2:K$72, ROW())} -> YARDIES | J2: =VLOOKUP(I2, Settings!$A$3:$C$12, 3, FALSE) -> ESTEEMED | K2: {=INDEX('BACKEND 1'!$V$28:$AK$38, MATCH(I2, 'BACKEND 1'!$V$28:$V$38, 0), MATCH(B2, 'BACKEND 1'!$V$28:$AK$28, 0))} -> 9 | L2: {=IFERROR(IF(D2=0,"-",INDEX('BACKEND 1'!$V$54:$AF$64, MATCH(D2, 'BACKEND 1'!$V$54:$V$64, 0), MATCH(K2, 'BACKEND 1'!$V$54:$AF$54, 0))),"-")} -> 11.707107 | M2: =_xlfn.RANK.EQ(L2,L2:L6,1) -> 4 | N2: =IF(G2 > H2, F2, IF(H2 > G2, I2, "Tie")) -> YARDIES | O2: =IF(G2 < H2, F2, IF(H2 < G2, I2, "Tie")) -> KINGS | P2: =IF(G2=0,"",IF(Q2 > 40, "YES", "")) | Q2: =IF(G2=0,"-",ABS(G2 - H2)) -> 14.25 | R2: =IF(G2=0,"-",G2 + H2) -> 298.69 | S2: =IF(AND(L2 <> 0, L2 = MINIFS(L$2:L$72, B$2:B$72, B2)), "MOTW", "") | U2: =IF(OR(AND(K2>D2,H2>G2),AND(D2>K2, G2>H2)), "UPSET", "") | V2: 1 | W2: =IF(OR(N2=F2,N2=H2),1,0) -> 0 | X2: =IF(OR(N2="POPEYES"), IF(ROW()=2,1,IF(N1="POPEYES",X1+1,1)), 0) -> 0 | Z2: Closest Score Game, Winner | AC2: {=MIN(IF(Q2:Q71<>0,Q2:Q71))} -> 0.2 | AD2: {=INDEX(N2:N71, MATCH(AC2, Q2:Q71, 0))} -> MUTTS | AE2: {=INDEX(B2:B71, MATCH(AC2, Q2:Q71, 0))} -> WEEK 10 | AH2: =IFERROR(IF(G2=0,"-",_xlfn.RANK.EQ(Q2,$Q:$Q,1)+(COUNTIFS(Q:Q, Q2, G:G, ">" & G2))),"ERROR") -> 14 | AI2: =IFERROR(IF(G2=0,"-",_xlfn.RANK.EQ(Q2,$Q:$Q,0)+(COUNTIFS(Q:Q, Q2, AK:AK, "<" & AK2))),"ERROR") -> 57 | AJ2: =IFERROR(IF(G2=0,"-",_xlfn.RANK.EQ(R2,$R:$R,1)+(COUNTIFS(R:R, R2, AH:AH, "<" & AH2))),"ERROR") -> 21 | AK2: =IFERROR(IF(G2=0,"-",_xlfn.RANK.EQ(R2,$R:$R,0)+(COUNTIFS(R:R, R2, AH:AH, "<" & AH2))),"ERROR") -> 50 | AL2: =IFERROR(IF(G2=0,"-",AVERAGE(AH2,AK2)),"UPCOMING") -> 32 | AM2: =IFERROR(IF(G2=0,"-",_xlfn.RANK.EQ(AL2,AL:AL,1)+(COUNTIFS(AL:AL,AL2,AH:AH,"<"&AH2))),"UPCOMING") -> 29 | AN2: =IFERROR(IF(G2=0,"-",_xlfn.RANK.EQ(AL2,AL:AL,0)+(COUNTIFS(AL:AL,AL2,AI:AI,"<"&AI2))),"UPCOMING") -> 42 | AO2: =IFERROR(IF((AND(G2<>0, S2="MOTW")),AVERAGE(AH2,AK2),"-"),"UPCOMING") -> - | AP2: =IFERROR(IF(AND(G2<>0, S2="MOTW"), _xlfn.RANK.EQ(AO2, AO:AO, 1) + COUNTIFS(AO:AO, AO2, AH:AH, "<" & AH2), "UPCOMING"), "-") -> UPCOMING | AQ2: =_xlfn.RANK.EQ(L2,$L$2:$L$70,1)+COUNTIFS($L$2:$L$70,L2,$AM$2:$AM$70,"<"&AM2) -> 28 | AR2: =IFERROR(IF(AND(G2<>0, U2="UPSET"), L2,"NO UPSET"),"-") -> NO UPSET | AS2: =IFERROR(IF(AL2="NO UPSET","-",_xlfn.RANK.EQ(AR2,$AR$2:$AR$70,0)+COUNTIFS($AR$2:$AR$70,AR2,$AL$2:$AL$70,"<"&AL2)),"-") -> - | AV2: Top 20 | AW2: Game Value | AX2: Year | AY2: Week | AZ2: Winner | BA2: Opposing Team | BB2: Game Ref # | BC2: Score gap | BD2: Combined Scoring | BE2: MOTW | BG2: =_xlfn.RANK.EQ(BK2, $BK$2:$BK$10, 0) -> 2 | BH2: =Settings!A3 -> DECOUPES | BI2: =COUNTIFS('Weekly Scores'!$N$2:$N$71, $BH2, 'Weekly Scores'!$G$2:$G$71, "<>", 'Weekly Scores'!$H$2:$H$71, "<>") -> 9 | BJ2: {=(SUMPRODUCT(((($F$1:$F$71=BH2)*($G$1:$G$71<$H$1:$H$71))+(($I$1:$I$71=BH2)*($H$1:$H$71<$G$1:$G$71)))*($G$1:$H$71<>"")))/2} -> 5 | BK2: =IFERROR(BI2 / (BI2 + BJ2),0) -> 0.64285714 | BL2: =VLOOKUP(BH2, Settings!A3:C10, 3, FALSE) -> PRODIGY | BM2: =COUNTIFS($E$2:$E$71,BL2,$J$2:$J$71,BL2,$N$2:$N$71,BH2,'Weekly Scores'!$G$2:$G$71, "<>") -> 5 | BN2: =ABS(COUNTIFS($E$2:$E$71,BL2,$J$2:$J$71,BL2,$F$2:$F$71,BH2,'Weekly Scores'!$G$2:$G$71, "<>0")+COUNTIFS($E$2:$E$71,BL2,$J$2:$J$71,BL2,$I$2:$I$71,BH2,'Weekly Scores'!$G$2:$G$71, "<>0")-BM2) -> 3 | BO2: =IFERROR(BM2 / (BM2 + BN2),0) -> 0.625 | BP2: =COUNTIFS($N$2:$N$71,$BH2,$S$2:$S$71,"MOTW",'Weekly Scores'!$G$2:$G$71, "<>") -> 0 | BQ2: =COUNTIFS($O$2:$O$71,$BH2,$S$2:$S$71,"MOTW",'Weekly Scores'!$G$2:$G$71, "<>") -> 2 | BR2: =IFERROR(BP2 / (BP2 + BQ2),0) -> 0 | BS2: =BP2+BQ2 -> 2 | BT2: =_xlfn.RANK.EQ(BS2,$BS$2:$BS$11,0)+COUNTIFS($BS$2:$BS$11,BS2,$BR$2:$BR$11,">"&BR2) -> 6 | BU2: =COUNTIFS($N$2:$N$71,$BH2,$U$2:$U$71,"UPSET",'Weekly Scores'!$G$2:$G$71, "<>") -> 4 | BW2: =COUNTIFS($N$2:$N$71,$BH2,$P$2:$P$71,"YES",'Weekly Scores'!$G$2:$G$71, "<>") -> 4 | BX2: =COUNTIFS('Weekly Scores'!$N$2:$N$71, $BH2, 'Weekly Scores'!$G$2:$G$71, "<>", 'Weekly Scores'!$H$2:$H$71, "<>", $F$2:$F$71, $BH2) -> 5 | BY2: =(COUNTIFS('Weekly Scores'!$F$2:$F$71, $BH2, 'Weekly Scores'!$G$2:$G$71, "<>0", 'Weekly Scores'!$H$2:$H$71,"<>0"))-BX2 -> 2 | BZ2: =IFERROR(BX2 / (BX2 + BY2),0) -> 0.71428571 | CA2: =COUNTIFS('Weekly Scores'!$N$2:$N$71, $BH2, 'Weekly Scores'!$G$2:$G$71, "<>", 'Weekly Scores'!$H$2:$H$71, "<>", $I$2:$I$71, $BH2) -> 4 | CB2: =(COUNTIFS('Weekly Scores'!$I$2:$I$71, $BH2, 'Weekly Scores'!$G$2:$G$71, "<>0", 'Weekly Scores'!$H$2:$H$71,"<>0"))-CA2 -> 3 | CC2: =IFERROR(CA2 / (CA2 + CB2),0) -> 0.57142857 | CE2: =IF(AND(CF2=0, CG2=0), 0, (CF2+CG2)/IF(CF2=0, 1, IF(CG2=0, 1, 2))) -> 12.30243 | CF2: =IFERROR(AVERAGEIFS(L:L,I:I,BH2),0) -> 10.835606 | CG2: =IFERROR(AVERAGEIFS(L:L,F:F,BH2),0) -> 13.769254 | CH2: =RANK(CE2,CE$2:CE$11,1) -> 4
A3: 2 | B3: {=INDEX(Settings!H$2:H$72, ROW())} -> WEEK 1 | C3: {=INDEX(Settings!I$2:I$72, ROW())} -> GAME 2 | D3: {=INDEX('BACKEND 1'!$V$28:$AK$38, MATCH(F3, 'BACKEND 1'!$V$28:$V$38, 0), MATCH(B3, 'BACKEND 1'!$V$28:$AK$28, 0))} -> 8 | E3: =VLOOKUP(F3, Settings!$A$3:$C$12, 3, FALSE) -> ESTEEMED | F3: {=INDEX(Settings!J$2:J$72, ROW())} -> MUTTS | G3: =SUMIFS('All-Stars'!E:E, 'All-Stars'!B:B, F3, 'All-Stars'!F:F, B3) -> 175.61 | H3: =SUMIFS('All-Stars'!E:E, 'All-Stars'!B:B, I3, 'All-Stars'!F:F, B3) -> 151.79 | I3: {=INDEX(Settings!K$2:K$72, ROW())} -> METAMOOKDAWGS | J3: =VLOOKUP(I3, Settings!$A$3:$C$12, 3, FALSE) -> ESTEEMED | K3: {=INDEX('BACKEND 1'!$V$28:$AK$38, MATCH(I3, 'BACKEND 1'!$V$28:$V$38, 0), MATCH(B3, 'BACKEND 1'!$V$28:$AK$28, 0))} -> 3 | L3: {=IFERROR(IF(D3=0,"-",INDEX('BACKEND 1'!$V$54:$AF$64, MATCH(D3, 'BACKEND 1'!$V$54:$V$64, 0), MATCH(K3, 'BACKEND 1'!$V$54:$AF$54, 0))),"-")} -> 16.535534 | M3: =_xlfn.RANK.EQ(L3,L2:L6,1) -> 5 | N3: =IF(G3 > H3, F3, IF(H3 > G3, I3, "Tie")) -> MUTTS | O3: =IF(G3 < H3, F3, IF(H3 < G3, I3, "Tie")) -> METAMOOKDAWGS | P3: =IF(G3=0,"",IF(Q3 > 40, "YES", "")) | Q3: =IF(G3=0,"-",ABS(G3 - H3)) -> 23.82 | R3: =IF(G3=0,"-",G3 + H3) -> 327.4 | S3: =IF(AND(L3 <> 0, L3 = MINIFS(L$2:L$72, B$2:B$72, B3)), "MOTW", "") | U3: =IF(OR(AND(K3>D3,H3>G3),AND(D3>K3, G3>H3)), "UPSET", "") -> UPSET | V3: 1 | W3: =IF(OR(N3=F3,N3=H3),1,0) -> 1 | X3: =IF(OR(N3="POPEYES"), IF(ROW()=2,1,IF(N2="POPEYES",X2+1,1)), 0) -> 0 | Z3: Biggiest Blowout Game, Winner | AC3: =MAX(Q2:Q71) -> 136.87 | AD3: {=INDEX(N2:N71, MATCH(AC3, Q2:Q71, 0))} -> CHAMPS | AE3: {=INDEX(B2:B71, MATCH(AC3, Q2:Q71, 0))} -> WEEK 3 | AH3: =IFERROR(IF(G3=0,"-",_xlfn.RANK.EQ(Q3,$Q:$Q,1)+(COUNTIFS(Q:Q, Q3, G:G, ">" & G3))),"ERROR") -> 21 | AI3: =IFERROR(IF(G3=0,"-",_xlfn.RANK.EQ(Q3,$Q:$Q,0)+(COUNTIFS(Q:Q, Q3, AK:AK, "<" & AK3))),"ERROR") -> 50 | AJ3: =IFERROR(IF(G3=0,"-",_xlfn.RANK.EQ(R3,$R:$R,1)+(COUNTIFS(R:R, R3, AH:AH, "<" & AH3))),"ERROR") -> 40 | AK3: =IFERROR(IF(G3=0,"-",_xlfn.RANK.EQ(R3,$R:$R,0)+(COUNTIFS(R:R, R3, AH:AH, "<" & AH3))),"ERROR") -> 31 | AL3: =IFERROR(IF(G3=0,"-",AVERAGE(AH3,AK3)),"UPCOMING") -> 26 | AM3: =IFERROR(IF(G3=0,"-",_xlfn.RANK.EQ(AL3,AL:AL,1)+(COUNTIFS(AL:AL,AL3,AH:AH,"<"&AH3))),"UPCOMING") -> 18 | AN3: =IFERROR(IF(G3=0,"-",_xlfn.RANK.EQ(AL3,AL:AL,0)+(COUNTIFS(AL:AL,AL3,AI:AI,"<"&AI3))),"UPCOMING") -> 53 | AO3: =IFERROR(IF((AND(G3<>0, S3="MOTW")),AVERAGE(AH3,AK3),"-"),"UPCOMING") -> - | AP3: =IFERROR(IF(AND(G3<>0, S3="MOTW"), _xlfn.RANK.EQ(AO3, AO:AO, 1) + COUNTIFS(AO:AO, AO3, AH:AH, "<" & AH3), "UPCOMING"), "-") -> UPCOMING | AQ3: =_xlfn.RANK.EQ(L3,$L$2:$L$70,1)+COUNTIFS($L$2:$L$70,L3,$AM$2:$AM$70,"<"&AM3) -> 50 | AR3: =IFERROR(IF(AND(G3<>0, U3="UPSET"), L3,"NO UPSET"),"-") -> 16.535534 | AS3: =IFERROR(IF(AL3="NO UPSET","-",_xlfn.RANK.EQ(AR3,$AR$2:$AR$70,0)+COUNTIFS($AR$2:$AR$70,AR3,$AL$2:$AL$70,"<"&AL3)),"-") -> 12 | AV3: 1 | AW3: =INDEX($AL:$AL, MATCH(AV3,$AP:$AP,0)) -> 6.5 | AX3: =Settings!$R$3 -> 2025 | AY3: =INDEX($B:$B, MATCH(AV3,$AP:$AP,0)) -> WEEK 3 | AZ3: =INDEX($N:$N, MATCH(AV3,$AP:$AP,0)) -> POPEYES | BA3: =INDEX($O:$O, MATCH(AV3,$AP:$AP,0)) -> MUTTS | BB3: {=Settings!$R$3 & " REG, PVE FFL GAME " & INDEX($A:$A, MATCH(AV3,$AP:$AP,0))} -> 2025 REG, PVE FFL GAME 12 | BC3: =INDEX($Q:$Q, MATCH(AV3,$AP:$AP,0)) -> 10.51 | BD3: =INDEX($R:$R, MATCH(AV3,$AP:$AP,0)) -> 381.93 | BE3: =INDEX($S:$S, MATCH(AV3,$AP:$AP,0)) -> MOTW | BG3: =_xlfn.RANK.EQ(BK3, $BK$2:$BK$10, 0) -> 4 | BH3: =Settings!A4 -> POPEYES | BI3: =COUNTIFS('Weekly Scores'!$N$2:$N$71, $BH3, 'Weekly Scores'!$G$2:$G$71, "<>", 'Weekly Scores'!$H$2:$H$71, "<>") -> 7 | BJ3: {=(SUMPRODUCT(((($F$1:$F$71=BH3)*($G$1:$G$71<$H$1:$H$71))+(($I$1:$I$71=BH3)*($H$1:$H$71<$G$1:$G$71)))*($G$1:$H$71<>"")))/2} -> 7 | BK3: =IFERROR(BI3 / (BI3 + BJ3),0) -> 0.5 | BL3: =VLOOKUP(BH3, Settings!A4:C11, 3, FALSE) -> PRODIGY | BM3: =COUNTIFS($E$2:$E$71,BL3,$J$2:$J$71,BL3,$N$2:$N$71,BH3,'Weekly Scores'!$G$2:$G$71, "<>") -> 2 | BN3: =ABS(COUNTIFS($E$2:$E$71,BL3,$J$2:$J$71,BL3,$F$2:$F$71,BH3,'Weekly Scores'!$G$2:$G$71, "<>0")+COUNTIFS($E$2:$E$71,BL3,$J$2:$J$71,BL3,$I$2:$I$71,BH3,'Weekly Scores'!$G$2:$G$71, "<>0")-BM3) -> 6 | BO3: =IFERROR(BM3 / (BM3 + BN3),0) -> 0.25 | BP3: =COUNTIFS($N$2:$N$71,$BH3,$S$2:$S$71,"MOTW",'Weekly Scores'!$G$2:$G$71, "<>") -> 3 | BQ3: =COUNTIFS($O$2:$O$71,$BH3,$S$2:$S$71,"MOTW",'Weekly Scores'!$G$2:$G$71, "<>") -> 1 | BR3: =IFERROR(BP3 / (BP3 + BQ3),0) -> 0.75 | BS3: =BP3+BQ3 -> 4 | BT3: =_xlfn.RANK.EQ(BS3,$BS$2:$BS$11,0)+COUNTIFS($BS$2:$BS$11,BS3,$BR$2:$BR$11,">"&BR3) -> 3 | BU3: =COUNTIFS($N$2:$N$71,$BH3,$U$2:$U$71,"UPSET",'Weekly Scores'!$G$2:$G$71, "<>") -> 2 | BW3: =COUNTIFS($N$2:$N$71,$BH3,$P$2:$P$71,"YES",'Weekly Scores'!$G$2:$G$71, "<>") -> 2 | BX3: =COUNTIFS('Weekly Scores'!$N$2:$N$71, $BH3, 'Weekly Scores'!$G$2:$G$71, "<>", 'Weekly Scores'!$H$2:$H$71, "<>", $F$2:$F$71, $BH3) -> 4 | BY3: =(COUNTIFS('Weekly Scores'!$F$2:$F$71, $BH3, 'Weekly Scores'!$G$2:$G$71, "<>0", 'Weekly Scores'!$H$2:$H$71,"<>0"))-BX3 -> 3 | BZ3: =IFERROR(BX3 / (BX3 + BY3),0) -> 0.57142857 | CA3: =COUNTIFS('Weekly Scores'!$N$2:$N$71, $BH3, 'Weekly Scores'!$G$2:$G$71, "<>", 'Weekly Scores'!$H$2:$H$71, "<>", $I$2:$I$71, $BH3) -> 3 | CB3: =(COUNTIFS('Weekly Scores'!$I$2:$I$71, $BH3, 'Weekly Scores'!$G$2:$G$71, "<>0", 'Weekly Scores'!$H$2:$H$71,"<>0"))-CA3 -> 4 | CC3: =IFERROR(CA3 / (CA3 + CB3),0) -> 0.42857143 | CE3: =IF(AND(CF3=0, CG3=0), 0, (CF3+CG3)/IF(CF3=0, 1, IF(CG3=0, 1, 2))) -> 11.424366 | CF3: =IFERROR(AVERAGEIFS(L:L,I:I,BH3),0) -> 11.912111 | CG3: =IFERROR(AVERAGEIFS(L:L,F:F,BH3),0) -> 10.936621 | CH3: =RANK(CE3,CE$2:CE$11,1) -> 1
A4: 3 | B4: {=INDEX(Settings!H$2:H$72, ROW())} -> WEEK 1 | C4: {=INDEX(Settings!I$2:I$72, ROW())} -> GAME 3 | D4: {=INDEX('BACKEND 1'!$V$28:$AK$38, MATCH(F4, 'BACKEND 1'!$V$28:$V$38, 0), MATCH(B4, 'BACKEND 1'!$V$28:$AK$28, 0))} -> 7 | E4: =VLOOKUP(F4, Settings!$A$3:$C$12, 3, FALSE) -> ESTEEMED | F4: {=INDEX(Settings!J$2:J$72, ROW())} -> EAGLES | G4: =SUMIFS('All-Stars'!E:E, 'All-Stars'!B:B, F4, 'All-Stars'!F:F, B4) -> 151.12 | H4: =SUMIFS('All-Stars'!E:E, 'All-Stars'!B:B, I4, 'All-Stars'!F:F, B4) -> 177.91 | I4: {=INDEX(Settings!K$2:K$72, ROW())} -> CHAMPS | J4: =VLOOKUP(I4, Settings!$A$3:$C$12, 3, FALSE) -> ESTEEMED | K4: {=INDEX('BACKEND 1'!$V$28:$AK$38, MATCH(I4, 'BACKEND 1'!$V$28:$V$38, 0), MATCH(B4, 'BACKEND 1'!$V$28:$AK$28, 0))} -> 6 | L4: {=IFERROR(IF(D4=0,"-",INDEX('BACKEND 1'!$V$54:$AF$64, MATCH(D4, 'BACKEND 1'!$V$54:$V$64, 0), MATCH(K4, 'BACKEND 1'!$V$54:$AF$54, 0))),"-")} -> 8.7071068 | M4: =_xlfn.RANK.EQ(L4,L2:L6,1) -> 3 | N4: =IF(G4 > H4, F4, IF(H4 > G4, I4, "Tie")) -> CHAMPS | O4: =IF(G4 < H4, F4, IF(H4 < G4, I4, "Tie")) -> EAGLES | P4: =IF(G4=0,"",IF(Q4 > 40, "YES", "")) | Q4: =IF(G4=0,"-",ABS(G4 - H4)) -> 26.79 | R4: =IF(G4=0,"-",G4 + H4) -> 329.03 | S4: =IF(AND(L4 <> 0, L4 = MINIFS(L$2:L$72, B$2:B$72, B4)), "MOTW", "") | U4: =IF(OR(AND(K4>D4,H4>G4),AND(D4>K4, G4>H4)), "UPSET", "") | V4: 1 | W4: =IF(OR(N4=F4,N4=H4),1,0) -> 0 | X4: =IF(OR(N4="POPEYES"), IF(ROW()=2,1,IF(N3="POPEYES",X3+1,1)), 0) -> 0 | Z4: Highest Combined Score Game, Winner | AC4: =MAX(R2:R71) -> 422.51 | AD4: {=INDEX(N2:N71, MATCH(AC4, R2:R71, 0))} -> DECOUPES | AE4: {=INDEX(B2:B71, MATCH(AC4, R2:R71, 0))} -> WEEK 12 | AH4: =IFERROR(IF(G4=0,"-",_xlfn.RANK.EQ(Q4,$Q:$Q,1)+(COUNTIFS(Q:Q, Q4, G:G, ">" & G4))),"ERROR") -> 25 | AI4: =IFERROR(IF(G4=0,"-",_xlfn.RANK.EQ(Q4,$Q:$Q,0)+(COUNTIFS(Q:Q, Q4, AK:AK, "<" & AK4))),"ERROR") -> 46 | AJ4: =IFERROR(IF(G4=0,"-",_xlfn.RANK.EQ(R4,$R:$R,1)+(COUNTIFS(R:R, R4, AH:AH, "<" & AH4))),"ERROR") -> 42 | AK4: =IFERROR(IF(G4=0,"-",_xlfn.RANK.EQ(R4,$R:$R,0)+(COUNTIFS(R:R, R4, AH:AH, "<" & AH4))),"ERROR") -> 29 | AL4: =IFERROR(IF(G4=0,"-",AVERAGE(AH4,AK4)),"UPCOMING") -> 27 | AM4: =IFERROR(IF(G4=0,"-",_xlfn.RANK.EQ(AL4,AL:AL,1)+(COUNTIFS(AL:AL,AL4,AH:AH,"<"&AH4))),"UPCOMING") -> 22 | AN4: =IFERROR(IF(G4=0,"-",_xlfn.RANK.EQ(AL4,AL:AL,0)+(COUNTIFS(AL:AL,AL4,AI:AI,"<"&AI4))),"UPCOMING") -> 49 | AO4: =IFERROR(IF((AND(G4<>0, S4="MOTW")),AVERAGE(AH4,AK4),"-"),"UPCOMING") -> - | AP4: =IFERROR(IF(AND(G4<>0, S4="MOTW"), _xlfn.RANK.EQ(AO4, AO:AO, 1) + COUNTIFS(AO:AO, AO4, AH:AH, "<" & AH4), "UPCOMING"), "-") -> UPCOMING | AQ4: =_xlfn.RANK.EQ(L4,$L$2:$L$70,1)+COUNTIFS($L$2:$L$70,L4,$AM$2:$AM$70,"<"&AM4) -> 14 | AR4: =IFERROR(IF(AND(G4<>0, U4="UPSET"), L4,"NO UPSET"),"-") -> NO UPSET | AS4: =IFERROR(IF(AL4="NO UPSET","-",_xlfn.RANK.EQ(AR4,$AR$2:$AR$70,0)+COUNTIFS($AR$2:$AR$70,AR4,$AL$2:$AL$70,"<"&AL4)),"-") -> - | AV4: 2 | AW4: =INDEX($AL:$AL, MATCH(AV4,$AP:$AP,0)) -> 14.5 | AX4: =Settings!$R$3 -> 2025 | AY4: =INDEX($B:$B, MATCH(AV4,$AP:$AP,0)) -> WEEK 10 | AZ4: =INDEX($N:$N, MATCH(AV4,$AP:$AP,0)) -> POPEYES | BA4: =INDEX($O:$O, MATCH(AV4,$AP:$AP,0)) -> YARDIES | BB4: {=Settings!$R$3 & " REG, PVE FFL GAME " & INDEX($A:$A, MATCH(AV4,$AP:$AP,0))} -> 2025 REG, PVE FFL GAME 47 | BC4: =INDEX($Q:$Q, MATCH(AV4,$AP:$AP,0)) -> 24.14 | BD4: =INDEX($R:$R, MATCH(AV4,$AP:$AP,0)) -> 380.12 | BE4: =INDEX($S:$S, MATCH(AV4,$AP:$AP,0)) -> MOTW | BG4: =_xlfn.RANK.EQ(BK4, $BK$2:$BK$10, 0) -> 1 | BH4: =Settings!A5 -> GREEN | BI4: =COUNTIFS('Weekly Scores'!$N$2:$N$71, $BH4, 'Weekly Scores'!$G$2:$G$71, "<>", 'Weekly Scores'!$H$2:$H$71, "<>") -> 12 | BJ4: {=(SUMPRODUCT(((($F$1:$F$71=BH4)*($G$1:$G$71<$H$1:$H$71))+(($I$1:$I$71=BH4)*($H$1:$H$71<$G$1:$G$71)))*($G$1:$H$71<>"")))/2} -> 2 | BK4: =IFERROR(BI4 / (BI4 + BJ4),0) -> 0.85714286 | BL4: =VLOOKUP(BH4, Settings!A5:C12, 3, FALSE) -> PRODIGY | BM4: =COUNTIFS($E$2:$E$71,BL4,$J$2:$J$71,BL4,$N$2:$N$71,BH4,'Weekly Scores'!$G$2:$G$71, "<>") -> 6 | BN4: =ABS(COUNTIFS($E$2:$E$71,BL4,$J$2:$J$71,BL4,$F$2:$F$71,BH4,'Weekly Scores'!$G$2:$G$71, "<>0")+COUNTIFS($E$2:$E$71,BL4,$J$2:$J$71,BL4,$I$2:$I$71,BH4,'Weekly Scores'!$G$2:$G$71, "<>0")-BM4) -> 2 | BO4: =IFERROR(BM4 / (BM4 + BN4),0) -> 0.75 | BP4: =COUNTIFS($N$2:$N$71,$BH4,$S$2:$S$71,"MOTW",'Weekly Scores'!$G$2:$G$71, "<>") -> 4 | BQ4: =COUNTIFS($O$2:$O$71,$BH4,$S$2:$S$71,"MOTW",'Weekly Scores'!$G$2:$G$71, "<>") -> 0 | BR4: =IFERROR(BP4 / (BP4 + BQ4),0) -> 1 | BS4: =BP4+BQ4 -> 4 | BT4: =_xlfn.RANK.EQ(BS4,$BS$2:$BS$11,0)+COUNTIFS($BS$2:$BS$11,BS4,$BR$2:$BR$11,">"&BR4) -> 2 | BU4: =COUNTIFS($N$2:$N$71,$BH4,$U$2:$U$71,"UPSET",'Weekly Scores'!$G$2:$G$71, "<>") -> 2 | BW4: =COUNTIFS($N$2:$N$71,$BH4,$P$2:$P$71,"YES",'Weekly Scores'!$G$2:$G$71, "<>") -> 5 | BX4: =COUNTIFS('Weekly Scores'!$N$2:$N$71, $BH4, 'Weekly Scores'!$G$2:$G$71, "<>", 'Weekly Scores'!$H$2:$H$71, "<>", $F$2:$F$71, $BH4) -> 6 | BY4: =(COUNTIFS('Weekly Scores'!$F$2:$F$71, $BH4, 'Weekly Scores'!$G$2:$G$71, "<>0", 'Weekly Scores'!$H$2:$H$71,"<>0"))-BX4 -> 1 | BZ4: =IFERROR(BX4 / (BX4 + BY4),0) -> 0.85714286 | CA4: =COUNTIFS('Weekly Scores'!$N$2:$N$71, $BH4, 'Weekly Scores'!$G$2:$G$71, "<>", 'Weekly Scores'!$H$2:$H$71, "<>", $I$2:$I$71, $BH4) -> 6 | CB4: =(COUNTIFS('Weekly Scores'!$I$2:$I$71, $BH4, 'Weekly Scores'!$G$2:$G$71, "<>0", 'Weekly Scores'!$H$2:$H$71,"<>0"))-CA4 -> 1 | CC4: =IFERROR(CA4 / (CA4 + CB4),0) -> 0.85714286 | CE4: =IF(AND(CF4=0, CG4=0), 0, (CF4+CG4)/IF(CF4=0, 1, IF(CG4=0, 1, 2))) -> 12.109065 | CF4: =IFERROR(AVERAGEIFS(L:L,I:I,BH4),0) -> 10.633576 | CG4: =IFERROR(AVERAGEIFS(L:L,F:F,BH4),0) -> 13.584555 | CH4: =RANK(CE4,CE$2:CE$11,1) -> 3
A5: 4 | B5: {=INDEX(Settings!H$2:H$72, ROW())} -> WEEK 1 | C5: {=INDEX(Settings!I$2:I$72, ROW())} -> GAME 4 | D5: {=INDEX('BACKEND 1'!$V$28:$AK$38, MATCH(F5, 'BACKEND 1'!$V$28:$V$38, 0), MATCH(B5, 'BACKEND 1'!$V$28:$AK$28, 0))} -> 5 | E5: =VLOOKUP(F5, Settings!$A$3:$C$12, 3, FALSE) -> PRODIGY | F5: {=INDEX(Settings!J$2:J$72, ROW())} -> DECOUPES | G5: =SUMIFS('All-Stars'!E:E, 'All-Stars'!B:B, F5, 'All-Stars'!F:F, B5) -> 161.6 | H5: =SUMIFS('All-Stars'!E:E, 'All-Stars'!B:B, I5, 'All-Stars'!F:F, B5) -> 132.31 | I5: {=INDEX(Settings!K$2:K$72, ROW())} -> GREEN | J5: =VLOOKUP(I5, Settings!$A$3:$C$12, 3, FALSE) -> PRODIGY | K5: {=INDEX('BACKEND 1'!$V$28:$AK$38, MATCH(I5, 'BACKEND 1'!$V$28:$V$38, 0), MATCH(B5, 'BACKEND 1'!$V$28:$AK$28, 0))} -> 4 | L5: {=IFERROR(IF(D5=0,"-",INDEX('BACKEND 1'!$V$54:$AF$64, MATCH(D5, 'BACKEND 1'!$V$54:$V$64, 0), MATCH(K5, 'BACKEND 1'!$V$54:$AF$54, 0))),"-")} -> 6.7071068 | M5: =_xlfn.RANK.EQ(L5,L2:L6,1) -> 2 | N5: =IF(G5 > H5, F5, IF(H5 > G5, I5, "Tie")) -> DECOUPES | O5: =IF(G5 < H5, F5, IF(H5 < G5, I5, "Tie")) -> GREEN | P5: =IF(G5=0,"",IF(Q5 > 40, "YES", "")) | Q5: =IF(G5=0,"-",ABS(G5 - H5)) -> 29.29 | R5: =IF(G5=0,"-",G5 + H5) -> 293.91 | S5: =IF(AND(L5 <> 0, L5 = MINIFS(L$2:L$72, B$2:B$72, B5)), "MOTW", "") | U5: =IF(OR(AND(K5>D5,H5>G5),AND(D5>K5, G5>H5)), "UPSET", "") -> UPSET | V5: 1 | W5: =IF(OR(N5=F5,N5=H5),1,0) -> 1 | X5: =IF(OR(N5="POPEYES"), IF(ROW()=2,1,IF(N4="POPEYES",X4+1,1)), 0) -> 0 | AH5: =IFERROR(IF(G5=0,"-",_xlfn.RANK.EQ(Q5,$Q:$Q,1)+(COUNTIFS(Q:Q, Q5, G:G, ">" & G5))),"ERROR") -> 27 | AI5: =IFERROR(IF(G5=0,"-",_xlfn.RANK.EQ(Q5,$Q:$Q,0)+(COUNTIFS(Q:Q, Q5, AK:AK, "<" & AK5))),"ERROR") -> 44 | AJ5: =IFERROR(IF(G5=0,"-",_xlfn.RANK.EQ(R5,$R:$R,1)+(COUNTIFS(R:R, R5, AH:AH, "<" & AH5))),"ERROR") -> 19 | AK5: =IFERROR(IF(G5=0,"-",_xlfn.RANK.EQ(R5,$R:$R,0)+(COUNTIFS(R:R, R5, AH:AH, "<" & AH5))),"ERROR") -> 52 | AL5: =IFERROR(IF(G5=0,"-",AVERAGE(AH5,AK5)),"UPCOMING") -> 39.5 | AM5: =IFERROR(IF(G5=0,"-",_xlfn.RANK.EQ(AL5,AL:AL,1)+(COUNTIFS(AL:AL,AL5,AH:AH,"<"&AH5))),"UPCOMING") -> 45 | AN5: =IFERROR(IF(G5=0,"-",_xlfn.RANK.EQ(AL5,AL:AL,0)+(COUNTIFS(AL:AL,AL5,AI:AI,"<"&AI5))),"UPCOMING") -> 26 | AO5: =IFERROR(IF((AND(G5<>0, S5="MOTW")),AVERAGE(AH5,AK5),"-"),"UPCOMING") -> - | AP5: =IFERROR(IF(AND(G5<>0, S5="MOTW"), _xlfn.RANK.EQ(AO5, AO:AO, 1) + COUNTIFS(AO:AO, AO5, AH:AH, "<" & AH5), "UPCOMING"), "-") -> UPCOMING | AQ5: =_xlfn.RANK.EQ(L5,$L$2:$L$70,1)+COUNTIFS($L$2:$L$70,L5,$AM$2:$AM$70,"<"&AM5) -> 7 | AR5: =IFERROR(IF(AND(G5<>0, U5="UPSET"), L5,"NO UPSET"),"-") -> 6.7071068 | AS5: =IFERROR(IF(AL5="NO UPSET","-",_xlfn.RANK.EQ(AR5,$AR$2:$AR$70,0)+COUNTIFS($AR$2:$AR$70,AR5,$AL$2:$AL$70,"<"&AL5)),"-") -> 28 | AV5: 3 | AW5: =INDEX($AL:$AL, MATCH(AV5,$AP:$AP,0)) -> 15.5 | AX5: =Settings!$R$3 -> 2025 | AY5: =INDEX($B:$B, MATCH(AV5,$AP:$AP,0)) -> WEEK 5 | AZ5: =INDEX($N:$N, MATCH(AV5,$AP:$AP,0)) -> GREEN | BA5: =INDEX($O:$O, MATCH(AV5,$AP:$AP,0)) -> CHAMPS | BB5: {=Settings!$R$3 & " REG, PVE FFL GAME " & INDEX($A:$A, MATCH(AV5,$AP:$AP,0))} -> 2025 REG, PVE FFL GAME 25 | BC5: =INDEX($Q:$Q, MATCH(AV5,$AP:$AP,0)) -> 2.3 | BD5: =INDEX($R:$R, MATCH(AV5,$AP:$AP,0)) -> 332.02 | BE5: =INDEX($S:$S, MATCH(AV5,$AP:$AP,0)) -> MOTW | BG5: =_xlfn.RANK.EQ(BK5, $BK$2:$BK$10, 0) -> 7 | BH5: =Settings!A6 -> SAVAGES | BI5: =COUNTIFS('Weekly Scores'!$N$2:$N$71, $BH5, 'Weekly Scores'!$G$2:$G$71, "<>", 'Weekly Scores'!$H$2:$H$71, "<>") -> 5 | BJ5: {=(SUMPRODUCT(((($F$1:$F$71=BH5)*($G$1:$G$71<$H$1:$H$71))+(($I$1:$I$71=BH5)*($H$1:$H$71<$G$1:$G$71)))*($G$1:$H$71<>"")))/2} -> 9 | BK5: =IFERROR(BI5 / (BI5 + BJ5),0) -> 0.35714286 | BL5: =VLOOKUP(BH5, Settings!A6:C13, 3, FALSE) -> PRODIGY | BM5: =COUNTIFS($E$2:$E$71,BL5,$J$2:$J$71,BL5,$N$2:$N$71,BH5,'Weekly Scores'!$G$2:$G$71, "<>") -> 2 | BN5: =ABS(COUNTIFS($E$2:$E$71,BL5,$J$2:$J$71,BL5,$F$2:$F$71,BH5,'Weekly Scores'!$G$2:$G$71, "<>0")+COUNTIFS($E$2:$E$71,BL5,$J$2:$J$71,BL5,$I$2:$I$71,BH5,'Weekly Scores'!$G$2:$G$71, "<>0")-BM5) -> 6 | BO5: =IFERROR(BM5 / (BM5 + BN5),0) -> 0.25 | BP5: =COUNTIFS($N$2:$N$71,$BH5,$S$2:$S$71,"MOTW",'Weekly Scores'!$G$2:$G$71, "<>") -> 0 | BQ5: =COUNTIFS($O$2:$O$71,$BH5,$S$2:$S$71,"MOTW",'Weekly Scores'!$G$2:$G$71, "<>") -> 2 | BR5: =IFERROR(BP5 / (BP5 + BQ5),0) -> 0 | BS5: =BP5+BQ5 -> 2 | BT5: =_xlfn.RANK.EQ(BS5,$BS$2:$BS$11,0)+COUNTIFS($BS$2:$BS$11,BS5,$BR$2:$BR$11,">"&BR5) -> 6 | BU5: =COUNTIFS($N$2:$N$71,$BH5,$U$2:$U$71,"UPSET",'Weekly Scores'!$G$2:$G$71, "<>") -> 3 | BW5: =COUNTIFS($N$2:$N$71,$BH5,$P$2:$P$71,"YES",'Weekly Scores'!$G$2:$G$71, "<>") -> 2 | BX5: =COUNTIFS('Weekly Scores'!$N$2:$N$71, $BH5, 'Weekly Scores'!$G$2:$G$71, "<>", 'Weekly Scores'!$H$2:$H$71, "<>", $F$2:$F$71, $BH5) -> 2 | BY5: =(COUNTIFS('Weekly Scores'!$F$2:$F$71, $BH5, 'Weekly Scores'!$G$2:$G$71, "<>0", 'Weekly Scores'!$H$2:$H$71,"<>0"))-BX5 -> 5 | BZ5: =IFERROR(BX5 / (BX5 + BY5),0) -> 0.28571429 | CA5: =COUNTIFS('Weekly Scores'!$N$2:$N$71, $BH5, 'Weekly Scores'!$G$2:$G$71, "<>", 'Weekly Scores'!$H$2:$H$71, "<>", $I$2:$I$71, $BH5) -> 3 | CB5: =(COUNTIFS('Weekly Scores'!$I$2:$I$71, $BH5, 'Weekly Scores'!$G$2:$G$71, "<>0", 'Weekly Scores'!$H$2:$H$71,"<>0"))-CA5 -> 4 | CC5: =IFERROR(CA5 / (CA5 + CB5),0) -> 0.42857143 | CE5: =IF(AND(CF5=0, CG5=0), 0, (CF5+CG5)/IF(CF5=0, 1, IF(CG5=0, 1, 2))) -> 12.806019 | CF5: =IFERROR(AVERAGEIFS(L:L,I:I,BH5),0) -> 14.079478 | CG5: =IFERROR(AVERAGEIFS(L:L,F:F,BH5),0) -> 11.53256 | CH5: =RANK(CE5,CE$2:CE$11,1) -> 6
A6: 5 | B6: {=INDEX(Settings!H$2:H$72, ROW())} -> WEEK 1 | C6: {=INDEX(Settings!I$2:I$72, ROW())} -> GAME 5 | D6: {=INDEX('BACKEND 1'!$V$28:$AK$38, MATCH(F6, 'BACKEND 1'!$V$28:$V$38, 0), MATCH(B6, 'BACKEND 1'!$V$28:$AK$28, 0))} -> 2 | E6: =VLOOKUP(F6, Settings!$A$3:$C$12, 3, FALSE) -> PRODIGY | F6: {=INDEX(Settings!J$2:J$72, ROW())} -> SAVAGES | G6: =SUMIFS('All-Stars'!E:E, 'All-Stars'!B:B, F6, 'All-Stars'!F:F, B6) -> 116.99 | H6: =SUMIFS('All-Stars'!E:E, 'All-Stars'!B:B, I6, 'All-Stars'!F:F, B6) -> 156.56 | I6: {=INDEX(Settings!K$2:K$72, ROW())} -> POPEYES | J6: =VLOOKUP(I6, Settings!$A$3:$C$12, 3, FALSE) -> PRODIGY | K6: {=INDEX('BACKEND 1'!$V$28:$AK$38, MATCH(I6, 'BACKEND 1'!$V$28:$V$38, 0), MATCH(B6, 'BACKEND 1'!$V$28:$AK$28, 0))} -> 1 | L6: {=IFERROR(IF(D6=0,"-",INDEX('BACKEND 1'!$V$54:$AF$64, MATCH(D6, 'BACKEND 1'!$V$54:$V$64, 0), MATCH(K6, 'BACKEND 1'!$V$54:$AF$54, 0))),"-")} -> 3.7071068 | M6: =_xlfn.RANK.EQ(L6,L2:L6,1) -> 1 | N6: =IF(G6 > H6, F6, IF(H6 > G6, I6, "Tie")) -> POPEYES | O6: =IF(G6 < H6, F6, IF(H6 < G6, I6, "Tie")) -> SAVAGES | P6: =IF(G6=0,"",IF(Q6 > 40, "YES", "")) | Q6: =IF(G6=0,"-",ABS(G6 - H6)) -> 39.57 | R6: =IF(G6=0,"-",G6 + H6) -> 273.55 | S6: =IF(AND(L6 <> 0, L6 = MINIFS(L$2:L$72, B$2:B$72, B6)), "MOTW", "") -> MOTW | U6: =IF(OR(AND(K6>D6,H6>G6),AND(D6>K6, G6>H6)), "UPSET", "") | V6: 1 | W6: =IF(OR(N6=F6,N6=H6),1,0) -> 0 | X6: =IF(OR(N6="POPEYES"), IF(ROW()=2,1,IF(N5="POPEYES",X5+1,1)), 0) -> 1 | Z6: Highest Combined Score Game, Loser | AC6: =MAX(R2:R71) -> 422.51 | AD6: =IF(AF6 <> AD4, AF6, IF(AG6 <> AD4, AG6, "")) -> METAMOOKDAWGS | AF6: {=INDEX(F2:F71, MATCH(AC6, R2:R71, 0))} -> DECOUPES | AG6: {=INDEX(I2:I71, MATCH(AC6, R2:R71, 0))} -> METAMOOKDAWGS | AH6: =IFERROR(IF(G6=0,"-",_xlfn.RANK.EQ(Q6,$Q:$Q,1)+(COUNTIFS(Q:Q, Q6, G:G, ">" & G6))),"ERROR") -> 42 | AI6: =IFERROR(IF(G6=0,"-",_xlfn.RANK.EQ(Q6,$Q:$Q,0)+(COUNTIFS(Q:Q, Q6, AK:AK, "<" & AK6))),"ERROR") -> 29 | AJ6: =IFERROR(IF(G6=0,"-",_xlfn.RANK.EQ(R6,$R:$R,1)+(COUNTIFS(R:R, R6, AH:AH, "<" & AH6))),"ERROR") -> 7 | AK6: =IFERROR(IF(G6=0,"-",_xlfn.RANK.EQ(R6,$R:$R,0)+(COUNTIFS(R:R, R6, AH:AH, "<" & AH6))),"ERROR") -> 64 | AL6: =IFERROR(IF(G6=0,"-",AVERAGE(AH6,AK6)),"UPCOMING") -> 53 | AM6: =IFERROR(IF(G6=0,"-",_xlfn.RANK.EQ(AL6,AL:AL,1)+(COUNTIFS(AL:AL,AL6,AH:AH,"<"&AH6))),"UPCOMING") -> 62 | AN6: =IFERROR(IF(G6=0,"-",_xlfn.RANK.EQ(AL6,AL:AL,0)+(COUNTIFS(AL:AL,AL6,AI:AI,"<"&AI6))),"UPCOMING") -> 9 | AO6: =IFERROR(IF((AND(G6<>0, S6="MOTW")),AVERAGE(AH6,AK6),"-"),"UPCOMING") -> 53 | AP6: =IFERROR(IF(AND(G6<>0, S6="MOTW"), _xlfn.RANK.EQ(AO6, AO:AO, 1) + COUNTIFS(AO:AO, AO6, AH:AH, "<" & AH6), "UPCOMING"), "-") -> 14 | AQ6: =_xlfn.RANK.EQ(L6,$L$2:$L$70,1)+COUNTIFS($L$2:$L$70,L6,$AM$2:$AM$70,"<"&AM6) -> 2 | AR6: =IFERROR(IF(AND(G6<>0, U6="UPSET"), L6,"NO UPSET"),"-") -> NO UPSET | AS6: =IFERROR(IF(AL6="NO UPSET","-",_xlfn.RANK.EQ(AR6,$AR$2:$AR$70,0)+COUNTIFS($AR$2:$AR$70,AR6,$AL$2:$AL$70,"<"&AL6)),"-") -> - | AV6: 4 | AW6: =INDEX($AL:$AL, MATCH(AV6,$AP:$AP,0)) -> 18.5 | AX6: =Settings!$R$3 -> 2025 | AY6: =INDEX($B:$B, MATCH(AV6,$AP:$AP,0)) -> WEEK 9 | AZ6: =INDEX($N:$N, MATCH(AV6,$AP:$AP,0)) -> GREEN | BA6: =INDEX($O:$O, MATCH(AV6,$AP:$AP,0)) -> POPEYES | BB6: {=Settings!$R$3 & " REG, PVE FFL GAME " & INDEX($A:$A, MATCH(AV6,$AP:$AP,0))} -> 2025 REG, PVE FFL GAME 41 | BC6: =INDEX($Q:$Q, MATCH(AV6,$AP:$AP,0)) -> 12.62 | BD6: =INDEX($R:$R, MATCH(AV6,$AP:$AP,0)) -> 338.36 | BE6: =INDEX($S:$S, MATCH(AV6,$AP:$AP,0)) -> MOTW | BG6: =_xlfn.RANK.EQ(BK6, $BK$2:$BK$10, 0) -> 7 | BH6: =Settings!A12 -> KINGS | BI6: =COUNTIFS('Weekly Scores'!$N$2:$N$71, $BH6, 'Weekly Scores'!$G$2:$G$71, "<>", 'Weekly Scores'!$H$2:$H$71, "<>") -> 5 | BJ6: {=(SUMPRODUCT(((($F$1:$F$71=BH6)*($G$1:$G$71<$H$1:$H$71))+(($I$1:$I$71=BH6)*($H$1:$H$71<$G$1:$G$71)))*($G$1:$H$71<>"")))/2} -> 9 | BK6: =IFERROR(BI6 / (BI6 + BJ6),0) -> 0.35714286 | BL6: =VLOOKUP(BH6, Settings!A12:C19, 3, FALSE) -> PRODIGY | BM6: =COUNTIFS($E$2:$E$71,BL6,$J$2:$J$71,BL6,$N$2:$N$71,BH6,'Weekly Scores'!$G$2:$G$71, "<>") -> 5 | BN6: =ABS(COUNTIFS($E$2:$E$71,BL6,$J$2:$J$71,BL6,$F$2:$F$71,BH6,'Weekly Scores'!$G$2:$G$71, "<>0")+COUNTIFS($E$2:$E$71,BL6,$J$2:$J$71,BL6,$I$2:$I$71,BH6,'Weekly Scores'!$G$2:$G$71, "<>0")-BM6) -> 3 | BO6: =IFERROR(BM6 / (BM6 + BN6),0) -> 0.625 | BP6: =COUNTIFS($N$2:$N$71,$BH6,$S$2:$S$71,"MOTW",'Weekly Scores'!$G$2:$G$71, "<>") -> 0 | BQ6: =COUNTIFS($O$2:$O$71,$BH6,$S$2:$S$71,"MOTW",'Weekly Scores'!$G$2:$G$71, "<>") -> 1 | BR6: =IFERROR(BP6 / (BP6 + BQ6),0) -> 0 | BS6: =BP6+BQ6 -> 1 | BT6: =_xlfn.RANK.EQ(BS6,$BS$2:$BS$11,0)+COUNTIFS($BS$2:$BS$11,BS6,$BR$2:$BR$11,">"&BR6) -> 9 | BU6: =COUNTIFS($N$2:$N$71,$BH6,$U$2:$U$71,"UPSET",'Weekly Scores'!$G$2:$G$71, "<>") -> 5 | BW6: =COUNTIFS($N$2:$N$71,$BH6,$P$2:$P$71,"YES",'Weekly Scores'!$G$2:$G$71, "<>") -> 5 | BX6: =COUNTIFS('Weekly Scores'!$N$2:$N$71, $BH6, 'Weekly Scores'!$G$2:$G$71, "<>", 'Weekly Scores'!$H$2:$H$71, "<>", $F$2:$F$71, $BH6) -> 2 | BY6: =(COUNTIFS('Weekly Scores'!$F$2:$F$71, $BH6, 'Weekly Scores'!$G$2:$G$71, "<>0", 'Weekly Scores'!$H$2:$H$71,"<>0"))-BX6 -> 5 | BZ6: =IFERROR(BX6 / (BX6 + BY6),0) -> 0.28571429 | CA6: =COUNTIFS('Weekly Scores'!$N$2:$N$71, $BH6, 'Weekly Scores'!$G$2:$G$71, "<>", 'Weekly Scores'!$H$2:$H$71, "<>", $I$2:$I$71, $BH6) -> 3 | CB6: =(COUNTIFS('Weekly Scores'!$I$2:$I$71, $BH6, 'Weekly Scores'!$G$2:$G$71, "<>0", 'Weekly Scores'!$H$2:$H$71,"<>0"))-CA6 -> 4 | CC6: =IFERROR(CA6 / (CA6 + CB6),0) -> 0.42857143 | CE6: =IF(AND(CF6=0, CG6=0), 0, (CF6+CG6)/IF(CF6=0, 1, IF(CG6=0, 1, 2))) -> 14.281509 | CF6: =IFERROR(AVERAGEIFS(L:L,I:I,BH6),0) -> 12.877448 | CG6: =IFERROR(AVERAGEIFS(L:L,F:F,BH6),0) -> 15.68557 | CH6: =RANK(CE6,CE$2:CE$11,1) -> 9
A7: 6 | B7: {=INDEX(Settings!H$2:H$72, ROW())} -> WEEK 2 | C7: {=INDEX(Settings!I$2:I$72, ROW())} -> GAME 1 | D7: {=INDEX('BACKEND 1'!$V$28:$AK$38, MATCH(F7, 'BACKEND 1'!$V$28:$V$38, 0), MATCH(B7, 'BACKEND 1'!$V$28:$AK$28, 0))} -> 7 | E7: =VLOOKUP(F7, Settings!$A$3:$C$12, 3, FALSE) -> ESTEEMED | F7: {=INDEX(Settings!J$2:J$72, ROW())} -> METAMOOKDAWGS | G7: =SUMIFS('All-Stars'!E:E, 'All-Stars'!B:B, F7, 'All-Stars'!F:F, B7) -> 133.69 | H7: =SUMIFS('All-Stars'!E:E, 'All-Stars'!B:B, I7, 'All-Stars'!F:F, B7) -> 178.73 | I7: {=INDEX(Settings!K$2:K$72, ROW())} -> YARDIES | J7: =VLOOKUP(I7, Settings!$A$3:$C$12, 3, FALSE) -> ESTEEMED | K7: {=INDEX('BACKEND 1'!$V$28:$AK$38, MATCH(I7, 'BACKEND 1'!$V$28:$V$38, 0), MATCH(B7, 'BACKEND 1'!$V$28:$AK$28, 0))} -> 5 | L7: {=IFERROR(IF(D7=0,"-",INDEX('BACKEND 1'!$V$54:$AF$64, MATCH(D7, 'BACKEND 1'!$V$54:$V$64, 0), MATCH(K7, 'BACKEND 1'!$V$54:$AF$54, 0))),"-")} -> 10.414214 | M7: =_xlfn.RANK.EQ(L7,L7:L11,1) -> 2 | N7: =IF(G7 > H7, F7, IF(H7 > G7, I7, "Tie")) -> YARDIES | O7: =IF(G7 < H7, F7, IF(H7 < G7, I7, "Tie")) -> METAMOOKDAWGS | P7: =IF(G7=0,"",IF(Q7 > 40, "YES", "")) -> YES | Q7: =IF(G7=0,"-",ABS(G7 - H7)) -> 45.04 | R7: =IF(G7=0,"-",G7 + H7) -> 312.42 | S7: =IF(AND(L7 <> 0, L7 = MINIFS(L$2:L$72, B$2:B$72, B7)), "MOTW", "") | U7: =IF(OR(AND(K7>D7,H7>G7),AND(D7>K7, G7>H7)), "UPSET", "") | V7: 2 | W7: =IF(OR(N7=F7,N7=H7),1,0) -> 0 | X7: =IF(OR(N7="POPEYES"), IF(ROW()=2,1,IF(N6="POPEYES",X6+1,1)), 0) -> 0 | Z7: Highest Rank Game, Winner | AC7: {=MIN(IF(L2:L71<>0,L2:L71))} -> 3.7071068 | AD7: {=INDEX(N2:N71, MATCH(AC7, L2:L71, 0))} -> POPEYES | AE7: {=INDEX(B2:B71, MATCH(AC7, L2:L71, 0))} -> WEEK 1 | AH7: =IFERROR(IF(G7=0,"-",_xlfn.RANK.EQ(Q7,$Q:$Q,1)+(COUNTIFS(Q:Q, Q7, G:G, ">" & G7))),"ERROR") -> 48 | AI7: =IFERROR(IF(G7=0,"-",_xlfn.RANK.EQ(Q7,$Q:$Q,0)+(COUNTIFS(Q:Q, Q7, AK:AK, "<" & AK7))),"ERROR") -> 23 | AJ7: =IFERROR(IF(G7=0,"-",_xlfn.RANK.EQ(R7,$R:$R,1)+(COUNTIFS(R:R, R7, AH:AH, "<" & AH7))),"ERROR") -> 32 | AK7: =IFERROR(IF(G7=0,"-",_xlfn.RANK.EQ(R7,$R:$R,0)+(COUNTIFS(R:R, R7, AH:AH, "<" & AH7))),"ERROR") -> 39 | AL7: =IFERROR(IF(G7=0,"-",AVERAGE(AH7,AK7)),"UPCOMING") -> 43.5 | AM7: =IFERROR(IF(G7=0,"-",_xlfn.RANK.EQ(AL7,AL:AL,1)+(COUNTIFS(AL:AL,AL7,AH:AH,"<"&AH7))),"UPCOMING") -> 48 | AN7: =IFERROR(IF(G7=0,"-",_xlfn.RANK.EQ(AL7,AL:AL,0)+(COUNTIFS(AL:AL,AL7,AI:AI,"<"&AI7))),"UPCOMING") -> 23 | AO7: =IFERROR(IF((AND(G7<>0, S7="MOTW")),AVERAGE(AH7,AK7),"-"),"UPCOMING") -> - | AP7: =IFERROR(IF(AND(G7<>0, S7="MOTW"), _xlfn.RANK.EQ(AO7, AO:AO, 1) + COUNTIFS(AO:AO, AO7, AH:AH, "<" & AH7), "UPCOMING"), "-") -> UPCOMING | AQ7: =_xlfn.RANK.EQ(L7,$L$2:$L$70,1)+COUNTIFS($L$2:$L$70,L7,$AM$2:$AM$70,"<"&AM7) -> 22 | AR7: =IFERROR(IF(AND(G7<>0, U7="UPSET"), L7,"NO UPSET"),"-") -> NO UPSET | AS7: =IFERROR(IF(AL7="NO UPSET","-",_xlfn.RANK.EQ(AR7,$AR$2:$AR$70,0)+COUNTIFS($AR$2:$AR$70,AR7,$AL$2:$AL$70,"<"&AL7)),"-") -> - | AV7: 5 | AW7: =INDEX($AL:$AL, MATCH(AV7,$AP:$AP,0)) -> 20 | AX7: =Settings!$R$3 -> 2025 | AY7: =INDEX($B:$B, MATCH(AV7,$AP:$AP,0)) -> WEEK 8 | AZ7: =INDEX($N:$N, MATCH(AV7,$AP:$AP,0)) -> GREEN | BA7: =INDEX($O:$O, MATCH(AV7,$AP:$AP,0)) -> DECOUPES | BB7: {=Settings!$R$3 & " REG, PVE FFL GAME " & INDEX($A:$A, MATCH(AV7,$AP:$AP,0))} -> 2025 REG, PVE FFL GAME 37 | BC7: =INDEX($Q:$Q, MATCH(AV7,$AP:$AP,0)) -> 22.65 | BD7: =INDEX($R:$R, MATCH(AV7,$AP:$AP,0)) -> 344.37 | BE7: =INDEX($S:$S, MATCH(AV7,$AP:$AP,0)) -> MOTW | BG7: =_xlfn.RANK.EQ(BK7, $BK$2:$BK$10, 0) -> 6 | BH7: =Settings!A7 -> CHAMPS | BI7: =COUNTIFS('Weekly Scores'!$N$2:$N$71, $BH7, 'Weekly Scores'!$G$2:$G$71, "<>", 'Weekly Scores'!$H$2:$H$71, "<>") -> 6 | BJ7: {=(SUMPRODUCT(((($F$1:$F$71=BH7)*($G$1:$G$71<$H$1:$H$71))+(($I$1:$I$71=BH7)*($H$1:$H$71<$G$1:$G$71)))*($G$1:$H$71<>"")))/2} -> 8 | BK7: =IFERROR(BI7 / (BI7 + BJ7),0) -> 0.42857143 | BL7: =VLOOKUP(BH7, Settings!A7:C14, 3, FALSE) -> ESTEEMED | BM7: =COUNTIFS($E$2:$E$71,BL7,$J$2:$J$71,BL7,$N$2:$N$71,BH7,'Weekly Scores'!$G$2:$G$71, "<>") -> 4 | BN7: =ABS(COUNTIFS($E$2:$E$71,BL7,$J$2:$J$71,BL7,$F$2:$F$71,BH7,'Weekly Scores'!$G$2:$G$71, "<>0")+COUNTIFS($E$2:$E$71,BL7,$J$2:$J$71,BL7,$I$2:$I$71,BH7,'Weekly Scores'!$G$2:$G$71, "<>0")-BM7) -> 4 | BO7: =IFERROR(BM7 / (BM7 + BN7),0) -> 0.5 | BP7: =COUNTIFS($N$2:$N$71,$BH7,$S$2:$S$71,"MOTW",'Weekly Scores'!$G$2:$G$71, "<>") -> 1 | BQ7: =COUNTIFS($O$2:$O$71,$BH7,$S$2:$S$71,"MOTW",'Weekly Scores'!$G$2:$G$71, "<>") -> 3 | BR7: =IFERROR(BP7 / (BP7 + BQ7),0) -> 0.25 | BS7: =BP7+BQ7 -> 4 | BT7: =_xlfn.RANK.EQ(BS7,$BS$2:$BS$11,0)+COUNTIFS($BS$2:$BS$11,BS7,$BR$2:$BR$11,">"&BR7) -> 5 | BU7: =COUNTIFS($N$2:$N$71,$BH7,$U$2:$U$71,"UPSET",'Weekly Scores'!$G$2:$G$71, "<>") -> 2 | BW7: =COUNTIFS($N$2:$N$71,$BH7,$P$2:$P$71,"YES",'Weekly Scores'!$G$2:$G$71, "<>") -> 3 | BX7: =COUNTIFS('Weekly Scores'!$N$2:$N$71, $BH7, 'Weekly Scores'!$G$2:$G$71, "<>", 'Weekly Scores'!$H$2:$H$71, "<>", $F$2:$F$71, $BH7) -> 2 | BY7: =(COUNTIFS('Weekly Scores'!$F$2:$F$71, $BH7, 'Weekly Scores'!$G$2:$G$71, "<>0", 'Weekly Scores'!$H$2:$H$71,"<>0"))-BX7 -> 5 | BZ7: =IFERROR(BX7 / (BX7 + BY7),0) -> 0.28571429 | CA7: =COUNTIFS('Weekly Scores'!$N$2:$N$71, $BH7, 'Weekly Scores'!$G$2:$G$71, "<>", 'Weekly Scores'!$H$2:$H$71, "<>", $I$2:$I$71, $BH7) -> 4 | CB7: =(COUNTIFS('Weekly Scores'!$I$2:$I$71, $BH7, 'Weekly Scores'!$G$2:$G$71, "<>0", 'Weekly Scores'!$H$2:$H$71,"<>0"))-CA7 -> 3 | CC7: =IFERROR(CA7 / (CA7 + CB7),0) -> 0.57142857 | CE7: =IF(AND(CF7=0, CG7=0), 0, (CF7+CG7)/IF(CF7=0, 1, IF(CG7=0, 1, 2))) -> 12.049892 | CF7: =IFERROR(AVERAGEIFS(L:L,I:I,BH7),0) -> 12.407035 | CG7: =IFERROR(AVERAGEIFS(L:L,F:F,BH7),0) -> 11.692749 | CH7: =RANK(CE7,CE$2:CE$11,1) -> 2
